Workbook
Name MesInforme: 'S-1'!$E$3
Name Publicadores: TblPublicadores[Nombre]
Name Publicadores: TblPublicadores[Nombre]
Name SegmentaciónDeDatos_Grupo: #N/A
Name SegmentaciónDeDatos_Mes: #N/A

Sheet S-1
A1: Informes de la congregación
B2: PREDICACIÓN Y ASISTENCIA A LAS REUNIONES (S-1)
B3: =PROPER(TEXT(MesInforme, "mmmm"))&" de "&YEAR(MesInforme) -> Enero de 1900 | E3: =EDATE(MAX(TblInformes[Mes]), -$F$3) -> 0 | F3: 0
B4: Introduzca el informe y haga clic en Enviar.
C6: Publicadores activos
C7: Cuente todas las personas de la congregación que informaron alguna participación en el ministerio un mes o más durante los pasados seis meses.
C8: =COUNTIF(TblPublicadores[Estatus],"=Activo")+COUNTIF(TblPublicadores[Estatus],"=Activo/Irregular") -> 0
C9: Promedio de asistencia a las reuniones del fin de semana
C10: =IFERROR(VLOOKUP(MesInforme,'S-88'!$A$22:$J$33,10,FALSE),VLOOKUP(MesInforme,'S-88'!$K$22:$T$33,10,FALSE)) -> #N/A
C14: Publicadores
C15: Cantidad de informes
C16: =COUNTIFS(TblInformes[Mes enviado],MesInforme,TblInformes[Predicó en el mes],TRUE,TblInformes[Tipo Publicador],"Publicador") -> 0
C17: Publicaciones (impresas y electrónicas)
C18: =SUMIFS(#REF!,TblInformes[Mes enviado],MesInforme,TblInformes[Predicó en el mes],TRUE,TblInformes[Tipo Publicador],"Publicador") -> #REF!
C19: Presentaciones de videos
C20: =SUMIFS(#REF!,TblInformes[Mes enviado],MesInforme,TblInformes[Predicó en el mes],TRUE,TblInformes[Tipo Publicador],"Publicador") -> #REF!
C21: Horas
C22: =SUMIFS(TblInformes[Horas],TblInformes[Mes enviado],MesInforme,TblInformes[Predicó en el mes],TRUE,TblInformes[Tipo Publicador],"Publicador") -> 0
C23: Revisitas
C24: =SUMIFS(#REF!,TblInformes[Mes enviado],MesInforme,TblInformes[Predicó en el mes],TRUE,TblInformes[Tipo Publicador],"Publicador") -> #REF!
C25: Cursos bíblicos
C26: =SUMIFS(TblInformes[Cursos bíblicos],TblInformes[Mes enviado],MesInforme,TblInformes[Predicó en el mes],TRUE,TblInformes[Tipo Publicador],"Publicador") -> 0
C30: Precursores auxiliares
C31: Cantidad de informes
C32: =COUNTIFS(TblInformes[Mes enviado],MesInforme,TblInformes[Horas],">0",TblInformes[Tipo Publicador],"Precursor auxiliar") -> 0
C33: Publicaciones (impresas y electrónicas)
C34: =SUMIFS(#REF!,TblInformes[Mes enviado],MesInforme,TblInformes[Horas],">0",TblInformes[Tipo Publicador],"Precursor auxiliar") -> #REF!
C35: Presentaciones de videos
C36: =SUMIFS(#REF!,TblInformes[Mes enviado],MesInforme,TblInformes[Horas],">0",TblInformes[Tipo Publicador],"Precursor auxiliar") -> #REF!
C37: Horas
C38: =SUMIFS(TblInformes[Horas],TblInformes[Mes enviado],MesInforme,TblInformes[Horas],">0",TblInformes[Tipo Publicador],"Precursor auxiliar") -> 0
C39: Revisitas
C40: =SUMIFS(#REF!,TblInformes[Mes enviado],MesInforme,TblInformes[Horas],">0",TblInformes[Tipo Publicador],"Precursor auxiliar") -> #REF!
C41: Cursos bíblicos
C42: =SUMIFS(TblInformes[Cursos bíblicos],TblInformes[Mes enviado],MesInforme,TblInformes[Horas],">0",TblInformes[Tipo Publicador],"Precursor auxiliar") -> 0
C46: Precursores regulares
C47: Cantidad de informes
C48: =COUNTIFS(TblInformes[Mes enviado],MesInforme,TblInformes[Horas],">0",TblInformes[Tipo Publicador],"Precursor regular") -> 0
C49: Publicaciones (impresas y electrónicas)
C50: =SUMIFS(#REF!,TblInformes[Mes enviado],MesInforme,TblInformes[Horas],">0",TblInformes[Tipo Publicador],"Precursor regular") -> #REF!
...

Sheet S-88
B1: REGISTRO DE ASISTENCIA A LAS REUNIONES DE CONGREGACIÓN
B2: Reunión de entre semana
B3: Año de servicio | C3: Primera Semana | D3: Segunda Semana | E3: Tercera Semana | F3: Cuarta Semana | G3: Quinta Semana | H3: Número de reuniones | I3: Asistencia total | J3: Promedio de asistencia semanal | L3: Año de servicio | M3: Primera Semana | N3: Segunda Semana | O3: Tercera Semana | P3: Cuarta Semana | Q3: Quinta Semana | R3: Número de reuniones | S3: Asistencia total | T3: Promedio de asistencia semanal
B4: =YEAR(MesInforme)-IF(MONTH(MesInforme)<9,1,0) -> 1899 | L4: =B4+1 -> 1900
A5: =DATE(B4-1,9,1) -> 693476 | B5: Septiembre | C5: =IFERROR(IF(ISBLANK(VLOOKUP($A5,'S-3'!$A:$K,COLUMN('S-3'!B$5),FALSE)),"",VLOOKUP($A5,'S-3'!$A:$K,COLUMN('S-3'!B$5),FALSE)),"") | D5: =IFERROR(IF(ISBLANK(VLOOKUP($A5,'S-3'!$A:$K,COLUMN('S-3'!C$5),FALSE)),"",VLOOKUP($A5,'S-3'!$A:$K,COLUMN('S-3'!C$5),FALSE)),"") | E5: =IFERROR(IF(ISBLANK(VLOOKUP($A5,'S-3'!$A:$K,COLUMN('S-3'!D$5),FALSE)),"",VLOOKUP($A5,'S-3'!$A:$K,COLUMN('S-3'!D$5),FALSE)),"") | F5: =IFERROR(IF(ISBLANK(VLOOKUP($A5,'S-3'!$A:$K,COLUMN('S-3'!E$5),FALSE)),"",VLOOKUP($A5,'S-3'!$A:$K,COLUMN('S-3'!E$5),FALSE)),"") | G5: =IFERROR(IF(ISBLANK(VLOOKUP($A5,'S-3'!$A:$K,COLUMN('S-3'!F$5),FALSE)),"",VLOOKUP($A5,'S-3'!$A:$K,COLUMN('S-3'!F$5),FALSE)),"") | H5: =IF(COUNT(C5:G5)=0,"",COUNT(C5:G5)) | I5: =IF(H5="","",SUM(C5:G5)) | J5: =IF(H5="","",I5/H5) | K5: =DATE(L4-1,9,1) -> 693841 | L5: Septiembre | M5: =IFERROR(IF(ISBLANK(VLOOKUP($K5,'S-3'!$A:$K,COLUMN('S-3'!B$5),FALSE)),"",VLOOKUP($K5,'S-3'!$A:$K,COLUMN('S-3'!B$5),FALSE)),"") | N5: =IFERROR(IF(ISBLANK(VLOOKUP($K5,'S-3'!$A:$K,COLUMN('S-3'!C$5),FALSE)),"",VLOOKUP($K5,'S-3'!$A:$K,COLUMN('S-3'!C$5),FALSE)),"") | O5: =IFERROR(IF(ISBLANK(VLOOKUP($K5,'S-3'!$A:$K,COLUMN('S-3'!D$5),FALSE)),"",VLOOKUP($K5,'S-3'!$A:$K,COLUMN('S-3'!D$5),FALSE)),"") | P5: =IFERROR(IF(ISBLANK(VLOOKUP($K5,'S-3'!$A:$K,COLUMN('S-3'!E$5),FALSE)),"",VLOOKUP($K5,'S-3'!$A:$K,COLUMN('S-3'!E$5),FALSE)),"") | Q5: =IFERROR(IF(ISBLANK(VLOOKUP($K5,'S-3'!$A:$K,COLUMN('S-3'!F$5),FALSE)),"",VLOOKUP($K5,'S-3'!$A:$K,COLUMN('S-3'!F$5),FALSE)),"") | R5: =IF(COUNT(M5:Q5)=0,"",COUNT(M5:Q5)) | S5: =IF(R5="","",SUM(M5:Q5)) | T5: =IF(R5="","",S5/R5)
A6: =EDATE(A5,1) -> 693506 | B6: Octubre | C6: =IFERROR(IF(ISBLANK(VLOOKUP($A6,'S-3'!$A:$K,COLUMN('S-3'!B$5),FALSE)),"",VLOOKUP($A6,'S-3'!$A:$K,COLUMN('S-3'!B$5),FALSE)),"") | D6: =IFERROR(IF(ISBLANK(VLOOKUP($A6,'S-3'!$A:$K,COLUMN('S-3'!C$5),FALSE)),"",VLOOKUP($A6,'S-3'!$A:$K,COLUMN('S-3'!C$5),FALSE)),"") | E6: =IFERROR(IF(ISBLANK(VLOOKUP($A6,'S-3'!$A:$K,COLUMN('S-3'!D$5),FALSE)),"",VLOOKUP($A6,'S-3'!$A:$K,COLUMN('S-3'!D$5),FALSE)),"") | F6: =IFERROR(IF(ISBLANK(VLOOKUP($A6,'S-3'!$A:$K,COLUMN('S-3'!E$5),FALSE)),"",VLOOKUP($A6,'S-3'!$A:$K,COLUMN('S-3'!E$5),FALSE)),"") | G6: =IFERROR(IF(ISBLANK(VLOOKUP($A6,'S-3'!$A:$K,COLUMN('S-3'!F$5),FALSE)),"",VLOOKUP($A6,'S-3'!$A:$K,COLUMN('S-3'!F$5),FALSE)),"") | H6: =IF(COUNT(C6:G6)=0,"",COUNT(C6:G6)) | I6: =IF(H6="","",SUM(C6:G6)) | J6: =IF(H6="","",I6/H6) | K6: =EDATE(K5,1) -> 693871 | L6: Octubre | M6: =IFERROR(IF(ISBLANK(VLOOKUP($K6,'S-3'!$A:$K,COLUMN('S-3'!B$5),FALSE)),"",VLOOKUP($K6,'S-3'!$A:$K,COLUMN('S-3'!B$5),FALSE)),"") | N6: =IFERROR(IF(ISBLANK(VLOOKUP($K6,'S-3'!$A:$K,COLUMN('S-3'!C$5),FALSE)),"",VLOOKUP($K6,'S-3'!$A:$K,COLUMN('S-3'!C$5),FALSE)),"") | O6: =IFERROR(IF(ISBLANK(VLOOKUP($K6,'S-3'!$A:$K,COLUMN('S-3'!D$5),FALSE)),"",VLOOKUP($K6,'S-3'!$A:$K,COLUMN('S-3'!D$5),FALSE)),"") | P6: =IFERROR(IF(ISBLANK(VLOOKUP($K6,'S-3'!$A:$K,COLUMN('S-3'!E$5),FALSE)),"",VLOOKUP($K6,'S-3'!$A:$K,COLUMN('S-3'!E$5),FALSE)),"") | Q6: =IFERROR(IF(ISBLANK(VLOOKUP($K6,'S-3'!$A:$K,COLUMN('S-3'!F$5),FALSE)),"",VLOOKUP($K6,'S-3'!$A:$K,COLUMN('S-3'!F$5),FALSE)),"") | R6: =IF(COUNT(M6:Q6)=0,"",COUNT(M6:Q6)) | S6: =IF(R6="","",SUM(M6:Q6)) | T6: =IF(R6="","",S6/R6)
A7: =EDATE(A6,1) -> 693537 | B7: Noviembre | C7: =IFERROR(IF(ISBLANK(VLOOKUP($A7,'S-3'!$A:$K,COLUMN('S-3'!B$5),FALSE)),"",VLOOKUP($A7,'S-3'!$A:$K,COLUMN('S-3'!B$5),FALSE)),"") | D7: =IFERROR(IF(ISBLANK(VLOOKUP($A7,'S-3'!$A:$K,COLUMN('S-3'!C$5),FALSE)),"",VLOOKUP($A7,'S-3'!$A:$K,COLUMN('S-3'!C$5),FALSE)),"") | E7: =IFERROR(IF(ISBLANK(VLOOKUP($A7,'S-3'!$A:$K,COLUMN('S-3'!D$5),FALSE)),"",VLOOKUP($A7,'S-3'!$A:$K,COLUMN('S-3'!D$5),FALSE)),"") | F7: =IFERROR(IF(ISBLANK(VLOOKUP($A7,'S-3'!$A:$K,COLUMN('S-3'!E$5),FALSE)),"",VLOOKUP($A7,'S-3'!$A:$K,COLUMN('S-3'!E$5),FALSE)),"") | G7: =IFERROR(IF(ISBLANK(VLOOKUP($A7,'S-3'!$A:$K,COLUMN('S-3'!F$5),FALSE)),"",VLOOKUP($A7,'S-3'!$A:$K,COLUMN('S-3'!F$5),FALSE)),"") | H7: =IF(COUNT(C7:G7)=0,"",COUNT(C7:G7)) | I7: =IF(H7="","",SUM(C7:G7)) | J7: =IF(H7="","",I7/H7) | K7: =EDATE(K6,1) -> 693902 | L7: Noviembre | M7: =IFERROR(IF(ISBLANK(VLOOKUP($K7,'S-3'!$A:$K,COLUMN('S-3'!B$5),FALSE)),"",VLOOKUP($K7,'S-3'!$A:$K,COLUMN('S-3'!B$5),FALSE)),"") | N7: =IFERROR(IF(ISBLANK(VLOOKUP($K7,'S-3'!$A:$K,COLUMN('S-3'!C$5),FALSE)),"",VLOOKUP($K7,'S-3'!$A:$K,COLUMN('S-3'!C$5),FALSE)),"") | O7: =IFERROR(IF(ISBLANK(VLOOKUP($K7,'S-3'!$A:$K,COLUMN('S-3'!D$5),FALSE)),"",VLOOKUP($K7,'S-3'!$A:$K,COLUMN('S-3'!D$5),FALSE)),"") | P7: =IFERROR(IF(ISBLANK(VLOOKUP($K7,'S-3'!$A:$K,COLUMN('S-3'!E$5),FALSE)),"",VLOOKUP($K7,'S-3'!$A:$K,COLUMN('S-3'!E$5),FALSE)),"") | Q7: =IFERROR(IF(ISBLANK(VLOOKUP($K7,'S-3'!$A:$K,COLUMN('S-3'!F$5),FALSE)),"",VLOOKUP($K7,'S-3'!$A:$K,COLUMN('S-3'!F$5),FALSE)),"") | R7: =IF(COUNT(M7:Q7)=0,"",COUNT(M7:Q7)) | S7: =IF(R7="","",SUM(M7:Q7)) | T7: =IF(R7="","",S7/R7)
A8: =EDATE(A7,1) -> 693567 | B8: Diciembre | C8: =IFERROR(IF(ISBLANK(VLOOKUP($A8,'S-3'!$A:$K,COLUMN('S-3'!B$5),FALSE)),"",VLOOKUP($A8,'S-3'!$A:$K,COLUMN('S-3'!B$5),FALSE)),"") | D8: =IFERROR(IF(ISBLANK(VLOOKUP($A8,'S-3'!$A:$K,COLUMN('S-3'!C$5),FALSE)),"",VLOOKUP($A8,'S-3'!$A:$K,COLUMN('S-3'!C$5),FALSE)),"") | E8: =IFERROR(IF(ISBLANK(VLOOKUP($A8,'S-3'!$A:$K,COLUMN('S-3'!D$5),FALSE)),"",VLOOKUP($A8,'S-3'!$A:$K,COLUMN('S-3'!D$5),FALSE)),"") | F8: =IFERROR(IF(ISBLANK(VLOOKUP($A8,'S-3'!$A:$K,COLUMN('S-3'!E$5),FALSE)),"",VLOOKUP($A8,'S-3'!$A:$K,COLUMN('S-3'!E$5),FALSE)),"") | G8: =IFERROR(IF(ISBLANK(VLOOKUP($A8,'S-3'!$A:$K,COLUMN('S-3'!F$5),FALSE)),"",VLOOKUP($A8,'S-3'!$A:$K,COLUMN('S-3'!F$5),FALSE)),"") | H8: =IF(COUNT(C8:G8)=0,"",COUNT(C8:G8)) | I8: =IF(H8="","",SUM(C8:G8)) | J8: =IF(H8="","",I8/H8) | K8: =EDATE(K7,1) -> 693932 | L8: Diciembre | M8: =IFERROR(IF(ISBLANK(VLOOKUP($K8,'S-3'!$A:$K,COLUMN('S-3'!B$5),FALSE)),"",VLOOKUP($K8,'S-3'!$A:$K,COLUMN('S-3'!B$5),FALSE)),"") | N8: =IFERROR(IF(ISBLANK(VLOOKUP($K8,'S-3'!$A:$K,COLUMN('S-3'!C$5),FALSE)),"",VLOOKUP($K8,'S-3'!$A:$K,COLUMN('S-3'!C$5),FALSE)),"") | O8: =IFERROR(IF(ISBLANK(VLOOKUP($K8,'S-3'!$A:$K,COLUMN('S-3'!D$5),FALSE)),"",VLOOKUP($K8,'S-3'!$A:$K,COLUMN('S-3'!D$5),FALSE)),"") | P8: =IFERROR(IF(ISBLANK(VLOOKUP($K8,'S-3'!$A:$K,COLUMN('S-3'!E$5),FALSE)),"",VLOOKUP($K8,'S-3'!$A:$K,COLUMN('S-3'!E$5),FALSE)),"") | Q8: =IFERROR(IF(ISBLANK(VLOOKUP($K8,'S-3'!$A:$K,COLUMN('S-3'!F$5),FALSE)),"",VLOOKUP($K8,'S-3'!$A:$K,COLUMN('S-3'!F$5),FALSE)),"") | R8: =IF(COUNT(M8:Q8)=0,"",COUNT(M8:Q8)) | S8: =IF(R8="","",SUM(M8:Q8)) | T8: =IF(R8="","",S8/R8)
A9: =EDATE(A8,1) -> 693598 | B9: Enero | C9: =IFERROR(IF(ISBLANK(VLOOKUP($A9,'S-3'!$A:$K,COLUMN('S-3'!B$5),FALSE)),"",VLOOKUP($A9,'S-3'!$A:$K,COLUMN('S-3'!B$5),FALSE)),"") | D9: =IFERROR(IF(ISBLANK(VLOOKUP($A9,'S-3'!$A:$K,COLUMN('S-3'!C$5),FALSE)),"",VLOOKUP($A9,'S-3'!$A:$K,COLUMN('S-3'!C$5),FALSE)),"") | E9: =IFERROR(IF(ISBLANK(VLOOKUP($A9,'S-3'!$A:$K,COLUMN('S-3'!D$5),FALSE)),"",VLOOKUP($A9,'S-3'!$A:$K,COLUMN('S-3'!D$5),FALSE)),"") | F9: =IFERROR(IF(ISBLANK(VLOOKUP($A9,'S-3'!$A:$K,COLUMN('S-3'!E$5),FALSE)),"",VLOOKUP($A9,'S-3'!$A:$K,COLUMN('S-3'!E$5),FALSE)),"") | G9: =IFERROR(IF(ISBLANK(VLOOKUP($A9,'S-3'!$A:$K,COLUMN('S-3'!F$5),FALSE)),"",VLOOKUP($A9,'S-3'!$A:$K,COLUMN('S-3'!F$5),FALSE)),"") | H9: =IF(COUNT(C9:G9)=0,"",COUNT(C9:G9)) | I9: =IF(H9="","",SUM(C9:G9)) | J9: =IF(H9="","",I9/H9) | K9: =EDATE(K8,1) -> 693963 | L9: Enero | M9: =IFERROR(IF(ISBLANK(VLOOKUP($K9,'S-3'!$A:$K,COLUMN('S-3'!B$5),FALSE)),"",VLOOKUP($K9,'S-3'!$A:$K,COLUMN('S-3'!B$5),FALSE)),"") | N9: =IFERROR(IF(ISBLANK(VLOOKUP($K9,'S-3'!$A:$K,COLUMN('S-3'!C$5),FALSE)),"",VLOOKUP($K9,'S-3'!$A:$K,COLUMN('S-3'!C$5),FALSE)),"") | O9: =IFERROR(IF(ISBLANK(VLOOKUP($K9,'S-3'!$A:$K,COLUMN('S-3'!D$5),FALSE)),"",VLOOKUP($K9,'S-3'!$A:$K,COLUMN('S-3'!D$5),FALSE)),"") | P9: =IFERROR(IF(ISBLANK(VLOOKUP($K9,'S-3'!$A:$K,COLUMN('S-3'!E$5),FALSE)),"",VLOOKUP($K9,'S-3'!$A:$K,COLUMN('S-3'!E$5),FALSE)),"") | Q9: =IFERROR(IF(ISBLANK(VLOOKUP($K9,'S-3'!$A:$K,COLUMN('S-3'!F$5),FALSE)),"",VLOOKUP($K9,'S-3'!$A:$K,COLUMN('S-3'!F$5),FALSE)),"") | R9: =IF(COUNT(M9:Q9)=0,"",COUNT(M9:Q9)) | S9: =IF(R9="","",SUM(M9:Q9)) | T9: =IF(R9="","",S9/R9)
A10: =EDATE(A9,1) -> 693629 | B10: Febrero | C10: =IFERROR(IF(ISBLANK(VLOOKUP($A10,'S-3'!$A:$K,COLUMN('S-3'!B$5),FALSE)),"",VLOOKUP($A10,'S-3'!$A:$K,COLUMN('S-3'!B$5),FALSE)),"") | D10: =IFERROR(IF(ISBLANK(VLOOKUP($A10,'S-3'!$A:$K,COLUMN('S-3'!C$5),FALSE)),"",VLOOKUP($A10,'S-3'!$A:$K,COLUMN('S-3'!C$5),FALSE)),"") | E10: =IFERROR(IF(ISBLANK(VLOOKUP($A10,'S-3'!$A:$K,COLUMN('S-3'!D$5),FALSE)),"",VLOOKUP($A10,'S-3'!$A:$K,COLUMN('S-3'!D$5),FALSE)),"") | F10: =IFERROR(IF(ISBLANK(VLOOKUP($A10,'S-3'!$A:$K,COLUMN('S-3'!E$5),FALSE)),"",VLOOKUP($A10,'S-3'!$A:$K,COLUMN('S-3'!E$5),FALSE)),"") | G10: =IFERROR(IF(ISBLANK(VLOOKUP($A10,'S-3'!$A:$K,COLUMN('S-3'!F$5),FALSE)),"",VLOOKUP($A10,'S-3'!$A:$K,COLUMN('S-3'!F$5),FALSE)),"") | H10: =IF(COUNT(C10:G10)=0,"",COUNT(C10:G10)) | I10: =IF(H10="","",SUM(C10:G10)) | J10: =IF(H10="","",I10/H10) | K10: =EDATE(K9,1) -> 693994 | L10: Febrero | M10: =IFERROR(IF(ISBLANK(VLOOKUP($K10,'S-3'!$A:$K,COLUMN('S-3'!B$5),FALSE)),"",VLOOKUP($K10,'S-3'!$A:$K,COLUMN('S-3'!B$5),FALSE)),"") | N10: =IFERROR(IF(ISBLANK(VLOOKUP($K10,'S-3'!$A:$K,COLUMN('S-3'!C$5),FALSE)),"",VLOOKUP($K10,'S-3'!$A:$K,COLUMN('S-3'!C$5),FALSE)),"") | O10: =IFERROR(IF(ISBLANK(VLOOKUP($K10,'S-3'!$A:$K,COLUMN('S-3'!D$5),FALSE)),"",VLOOKUP($K10,'S-3'!$A:$K,COLUMN('S-3'!D$5),FALSE)),"") | P10: =IFERROR(IF(ISBLANK(VLOOKUP($K10,'S-3'!$A:$K,COLUMN('S-3'!E$5),FALSE)),"",VLOOKUP($K10,'S-3'!$A:$K,COLUMN('S-3'!E$5),FALSE)),"") | Q10: =IFERROR(IF(ISBLANK(VLOOKUP($K10,'S-3'!$A:$K,COLUMN('S-3'!F$5),FALSE)),"",VLOOKUP($K10,'S-3'!$A:$K,COLUMN('S-3'!F$5),FALSE)),"") | R10: =IF(COUNT(M10:Q10)=0,"",COUNT(M10:Q10)) | S10: =IF(R10="","",SUM(M10:Q10)) | T10: =IF(R10="","",S10/R10)
A11: =EDATE(A10,1) -> 693657 | B11: Marzo | C11: =IFERROR(IF(ISBLANK(VLOOKUP($A11,'S-3'!$A:$K,COLUMN('S-3'!B$5),FALSE)),"",VLOOKUP($A11,'S-3'!$A:$K,COLUMN('S-3'!B$5),FALSE)),"") | D11: =IFERROR(IF(ISBLANK(VLOOKUP($A11,'S-3'!$A:$K,COLUMN('S-3'!C$5),FALSE)),"",VLOOKUP($A11,'S-3'!$A:$K,COLUMN('S-3'!C$5),FALSE)),"") | E11: =IFERROR(IF(ISBLANK(VLOOKUP($A11,'S-3'!$A:$K,COLUMN('S-3'!D$5),FALSE)),"",VLOOKUP($A11,'S-3'!$A:$K,COLUMN('S-3'!D$5),FALSE)),"") | F11: =IFERROR(IF(ISBLANK(VLOOKUP($A11,'S-3'!$A:$K,COLUMN('S-3'!E$5),FALSE)),"",VLOOKUP($A11,'S-3'!$A:$K,COLUMN('S-3'!E$5),FALSE)),"") | G11: =IFERROR(IF(ISBLANK(VLOOKUP($A11,'S-3'!$A:$K,COLUMN('S-3'!F$5),FALSE)),"",VLOOKUP($A11,'S-3'!$A:$K,COLUMN('S-3'!F$5),FALSE)),"") | H11: =IF(COUNT(C11:G11)=0,"",COUNT(C11:G11)) | I11: =IF(H11="","",SUM(C11:G11)) | J11: =IF(H11="","",I11/H11) | K11: =EDATE(K10,1) -> 694022 | L11: Marzo | M11: =IFERROR(IF(ISBLANK(VLOOKUP($K11,'S-3'!$A:$K,COLUMN('S-3'!B$5),FALSE)),"",VLOOKUP($K11,'S-3'!$A:$K,COLUMN('S-3'!B$5),FALSE)),"") | N11: =IFERROR(IF(ISBLANK(VLOOKUP($K11,'S-3'!$A:$K,COLUMN('S-3'!C$5),FALSE)),"",VLOOKUP($K11,'S-3'!$A:$K,COLUMN('S-3'!C$5),FALSE)),"") | O11: =IFERROR(IF(ISBLANK(VLOOKUP($K11,'S-3'!$A:$K,COLUMN('S-3'!D$5),FALSE)),"",VLOOKUP($K11,'S-3'!$A:$K,COLUMN('S-3'!D$5),FALSE)),"") | P11: =IFERROR(IF(ISBLANK(VLOOKUP($K11,'S-3'!$A:$K,COLUMN('S-3'!E$5),FALSE)),"",VLOOKUP($K11,'S-3'!$A:$K,COLUMN('S-3'!E$5),FALSE)),"") | Q11: =IFERROR(IF(ISBLANK(VLOOKUP($K11,'S-3'!$A:$K,COLUMN('S-3'!F$5),FALSE)),"",VLOOKUP($K11,'S-3'!$A:$K,COLUMN('S-3'!F$5),FALSE)),"") | R11: =IF(COUNT(M11:Q11)=0,"",COUNT(M11:Q11)) | S11: =IF(R11="","",SUM(M11:Q11)) | T11: =IF(R11="","",S11/R11)
A12: =EDATE(A11,1) -> 693688 | B12: Abril | C12: =IFERROR(IF(ISBLANK(VLOOKUP($A12,'S-3'!$A:$K,COLUMN('S-3'!B$5),FALSE)),"",VLOOKUP($A12,'S-3'!$A:$K,COLUMN('S-3'!B$5),FALSE)),"") | D12: =IFERROR(IF(ISBLANK(VLOOKUP($A12,'S-3'!$A:$K,COLUMN('S-3'!C$5),FALSE)),"",VLOOKUP($A12,'S-3'!$A:$K,COLUMN('S-3'!C$5),FALSE)),"") | E12: =IFERROR(IF(ISBLANK(VLOOKUP($A12,'S-3'!$A:$K,COLUMN('S-3'!D$5),FALSE)),"",VLOOKUP($A12,'S-3'!$A:$K,COLUMN('S-3'!D$5),FALSE)),"") | F12: =IFERROR(IF(ISBLANK(VLOOKUP($A12,'S-3'!$A:$K,COLUMN('S-3'!E$5),FALSE)),"",VLOOKUP($A12,'S-3'!$A:$K,COLUMN('S-3'!E$5),FALSE)),"") | G12: =IFERROR(IF(ISBLANK(VLOOKUP($A12,'S-3'!$A:$K,COLUMN('S-3'!F$5),FALSE)),"",VLOOKUP($A12,'S-3'!$A:$K,COLUMN('S-3'!F$5),FALSE)),"") | H12: =IF(COUNT(C12:G12)=0,"",COUNT(C12:G12)) | I12: =IF(H12="","",SUM(C12:G12)) | J12: =IF(H12="","",I12/H12) | K12: =EDATE(K11,1) -> 694053 | L12: Abril | M12: =IFERROR(IF(ISBLANK(VLOOKUP($K12,'S-3'!$A:$K,COLUMN('S-3'!B$5),FALSE)),"",VLOOKUP($K12,'S-3'!$A:$K,COLUMN('S-3'!B$5),FALSE)),"") | N12: =IFERROR(IF(ISBLANK(VLOOKUP($K12,'S-3'!$A:$K,COLUMN('S-3'!C$5),FALSE)),"",VLOOKUP($K12,'S-3'!$A:$K,COLUMN('S-3'!C$5),FALSE)),"") | O12: =IFERROR(IF(ISBLANK(VLOOKUP($K12,'S-3'!$A:$K,COLUMN('S-3'!D$5),FALSE)),"",VLOOKUP($K12,'S-3'!$A:$K,COLUMN('S-3'!D$5),FALSE)),"") | P12: =IFERROR(IF(ISBLANK(VLOOKUP($K12,'S-3'!$A:$K,COLUMN('S-3'!E$5),FALSE)),"",VLOOKUP($K12,'S-3'!$A:$K,COLUMN('S-3'!E$5),FALSE)),"") | Q12: =IFERROR(IF(ISBLANK(VLOOKUP($K12,'S-3'!$A:$K,COLUMN('S-3'!F$5),FALSE)),"",VLOOKUP($K12,'S-3'!$A:$K,COLUMN('S-3'!F$5),FALSE)),"") | R12: =IF(COUNT(M12:Q12)=0,"",COUNT(M12:Q12)) | S12: =IF(R12="","",SUM(M12:Q12)) | T12: =IF(R12="","",S12/R12)
A13: =EDATE(A12,1) -> 693718 | B13: Mayo | C13: =IFERROR(IF(ISBLANK(VLOOKUP($A13,'S-3'!$A:$K,COLUMN('S-3'!B$5),FALSE)),"",VLOOKUP($A13,'S-3'!$A:$K,COLUMN('S-3'!B$5),FALSE)),"") | D13: =IFERROR(IF(ISBLANK(VLOOKUP($A13,'S-3'!$A:$K,COLUMN('S-3'!C$5),FALSE)),"",VLOOKUP($A13,'S-3'!$A:$K,COLUMN('S-3'!C$5),FALSE)),"") | E13: =IFERROR(IF(ISBLANK(VLOOKUP($A13,'S-3'!$A:$K,COLUMN('S-3'!D$5),FALSE)),"",VLOOKUP($A13,'S-3'!$A:$K,COLUMN('S-3'!D$5),FALSE)),"") | F13: =IFERROR(IF(ISBLANK(VLOOKUP($A13,'S-3'!$A:$K,COLUMN('S-3'!E$5),FALSE)),"",VLOOKUP($A13,'S-3'!$A:$K,COLUMN('S-3'!E$5),FALSE)),"") | G13: =IFERROR(IF(ISBLANK(VLOOKUP($A13,'S-3'!$A:$K,COLUMN('S-3'!F$5),FALSE)),"",VLOOKUP($A13,'S-3'!$A:$K,COLUMN('S-3'!F$5),FALSE)),"") | H13: =IF(COUNT(C13:G13)=0,"",COUNT(C13:G13)) | I13: =IF(H13="","",SUM(C13:G13)) | J13: =IF(H13="","",I13/H13) | K13: =EDATE(K12,1) -> 694083 | L13: Mayo | M13: =IFERROR(IF(ISBLANK(VLOOKUP($K13,'S-3'!$A:$K,COLUMN('S-3'!B$5),FALSE)),"",VLOOKUP($K13,'S-3'!$A:$K,COLUMN('S-3'!B$5),FALSE)),"") | N13: =IFERROR(IF(ISBLANK(VLOOKUP($K13,'S-3'!$A:$K,COLUMN('S-3'!C$5),FALSE)),"",VLOOKUP($K13,'S-3'!$A:$K,COLUMN('S-3'!C$5),FALSE)),"") | O13: =IFERROR(IF(ISBLANK(VLOOKUP($K13,'S-3'!$A:$K,COLUMN('S-3'!D$5),FALSE)),"",VLOOKUP($K13,'S-3'!$A:$K,COLUMN('S-3'!D$5),FALSE)),"") | P13: =IFERROR(IF(ISBLANK(VLOOKUP($K13,'S-3'!$A:$K,COLUMN('S-3'!E$5),FALSE)),"",VLOOKUP($K13,'S-3'!$A:$K,COLUMN('S-3'!E$5),FALSE)),"") | Q13: =IFERROR(IF(ISBLANK(VLOOKUP($K13,'S-3'!$A:$K,COLUMN('S-3'!F$5),FALSE)),"",VLOOKUP($K13,'S-3'!$A:$K,COLUMN('S-3'!F$5),FALSE)),"") | R13: =IF(COUNT(M13:Q13)=0,"",COUNT(M13:Q13)) | S13: =IF(R13="","",SUM(M13:Q13)) | T13: =IF(R13="","",S13/R13)
A14: =EDATE(A13,1) -> 693749 | B14: Junio | C14: =IFERROR(IF(ISBLANK(VLOOKUP($A14,'S-3'!$A:$K,COLUMN('S-3'!B$5),FALSE)),"",VLOOKUP($A14,'S-3'!$A:$K,COLUMN('S-3'!B$5),FALSE)),"") | D14: =IFERROR(IF(ISBLANK(VLOOKUP($A14,'S-3'!$A:$K,COLUMN('S-3'!C$5),FALSE)),"",VLOOKUP($A14,'S-3'!$A:$K,COLUMN('S-3'!C$5),FALSE)),"") | E14: =IFERROR(IF(ISBLANK(VLOOKUP($A14,'S-3'!$A:$K,COLUMN('S-3'!D$5),FALSE)),"",VLOOKUP($A14,'S-3'!$A:$K,COLUMN('S-3'!D$5),FALSE)),"") | F14: =IFERROR(IF(ISBLANK(VLOOKUP($A14,'S-3'!$A:$K,COLUMN('S-3'!E$5),FALSE)),"",VLOOKUP($A14,'S-3'!$A:$K,COLUMN('S-3'!E$5),FALSE)),"") | G14: =IFERROR(IF(ISBLANK(VLOOKUP($A14,'S-3'!$A:$K,COLUMN('S-3'!F$5),FALSE)),"",VLOOKUP($A14,'S-3'!$A:$K,COLUMN('S-3'!F$5),FALSE)),"") | H14: =IF(COUNT(C14:G14)=0,"",COUNT(C14:G14)) | I14: =IF(H14="","",SUM(C14:G14)) | J14: =IF(H14="","",I14/H14) | K14: =EDATE(K13,1) -> 694114 | L14: Junio | M14: =IFERROR(IF(ISBLANK(VLOOKUP($K14,'S-3'!$A:$K,COLUMN('S-3'!B$5),FALSE)),"",VLOOKUP($K14,'S-3'!$A:$K,COLUMN('S-3'!B$5),FALSE)),"") | N14: =IFERROR(IF(ISBLANK(VLOOKUP($K14,'S-3'!$A:$K,COLUMN('S-3'!C$5),FALSE)),"",VLOOKUP($K14,'S-3'!$A:$K,COLUMN('S-3'!C$5),FALSE)),"") | O14: =IFERROR(IF(ISBLANK(VLOOKUP($K14,'S-3'!$A:$K,COLUMN('S-3'!D$5),FALSE)),"",VLOOKUP($K14,'S-3'!$A:$K,COLUMN('S-3'!D$5),FALSE)),"") | P14: =IFERROR(IF(ISBLANK(VLOOKUP($K14,'S-3'!$A:$K,COLUMN('S-3'!E$5),FALSE)),"",VLOOKUP($K14,'S-3'!$A:$K,COLUMN('S-3'!E$5),FALSE)),"") | Q14: =IFERROR(IF(ISBLANK(VLOOKUP($K14,'S-3'!$A:$K,COLUMN('S-3'!F$5),FALSE)),"",VLOOKUP($K14,'S-3'!$A:$K,COLUMN('S-3'!F$5),FALSE)),"") | R14: =IF(COUNT(M14:Q14)=0,"",COUNT(M14:Q14)) | S14: =IF(R14="","",SUM(M14:Q14)) | T14: =IF(R14="","",S14/R14)
A15: =EDATE(A14,1) -> 693779 | B15: Julio | C15: =IFERROR(IF(ISBLANK(VLOOKUP($A15,'S-3'!$A:$K,COLUMN('S-3'!B$5),FALSE)),"",VLOOKUP($A15,'S-3'!$A:$K,COLUMN('S-3'!B$5),FALSE)),"") | D15: =IFERROR(IF(ISBLANK(VLOOKUP($A15,'S-3'!$A:$K,COLUMN('S-3'!C$5),FALSE)),"",VLOOKUP($A15,'S-3'!$A:$K,COLUMN('S-3'!C$5),FALSE)),"") | E15: =IFERROR(IF(ISBLANK(VLOOKUP($A15,'S-3'!$A:$K,COLUMN('S-3'!D$5),FALSE)),"",VLOOKUP($A15,'S-3'!$A:$K,COLUMN('S-3'!D$5),FALSE)),"") | F15: =IFERROR(IF(ISBLANK(VLOOKUP($A15,'S-3'!$A:$K,COLUMN('S-3'!E$5),FALSE)),"",VLOOKUP($A15,'S-3'!$A:$K,COLUMN('S-3'!E$5),FALSE)),"") | G15: =IFERROR(IF(ISBLANK(VLOOKUP($A15,'S-3'!$A:$K,COLUMN('S-3'!F$5),FALSE)),"",VLOOKUP($A15,'S-3'!$A:$K,COLUMN('S-3'!F$5),FALSE)),"") | H15: =IF(COUNT(C15:G15)=0,"",COUNT(C15:G15)) | I15: =IF(H15="","",SUM(C15:G15)) | J15: =IF(H15="","",I15/H15) | K15: =EDATE(K14,1) -> 694144 | L15: Julio | M15: =IFERROR(IF(ISBLANK(VLOOKUP($K15,'S-3'!$A:$K,COLUMN('S-3'!B$5),FALSE)),"",VLOOKUP($K15,'S-3'!$A:$K,COLUMN('S-3'!B$5),FALSE)),"") | N15: =IFERROR(IF(ISBLANK(VLOOKUP($K15,'S-3'!$A:$K,COLUMN('S-3'!C$5),FALSE)),"",VLOOKUP($K15,'S-3'!$A:$K,COLUMN('S-3'!C$5),FALSE)),"") | O15: =IFERROR(IF(ISBLANK(VLOOKUP($K15,'S-3'!$A:$K,COLUMN('S-3'!D$5),FALSE)),"",VLOOKUP($K15,'S-3'!$A:$K,COLUMN('S-3'!D$5),FALSE)),"") | P15: =IFERROR(IF(ISBLANK(VLOOKUP($K15,'S-3'!$A:$K,COLUMN('S-3'!E$5),FALSE)),"",VLOOKUP($K15,'S-3'!$A:$K,COLUMN('S-3'!E$5),FALSE)),"") | Q15: =IFERROR(IF(ISBLANK(VLOOKUP($K15,'S-3'!$A:$K,COLUMN('S-3'!F$5),FALSE)),"",VLOOKUP($K15,'S-3'!$A:$K,COLUMN('S-3'!F$5),FALSE)),"") | R15: =IF(COUNT(M15:Q15)=0,"",COUNT(M15:Q15)) | S15: =IF(R15="","",SUM(M15:Q15)) | T15: =IF(R15="","",S15/R15)
A16: =EDATE(A15,1) -> 693810 | B16: Agosto | C16: =IFERROR(IF(ISBLANK(VLOOKUP($A16,'S-3'!$A:$K,COLUMN('S-3'!B$5),FALSE)),"",VLOOKUP($A16,'S-3'!$A:$K,COLUMN('S-3'!B$5),FALSE)),"") | D16: =IFERROR(IF(ISBLANK(VLOOKUP($A16,'S-3'!$A:$K,COLUMN('S-3'!C$5),FALSE)),"",VLOOKUP($A16,'S-3'!$A:$K,COLUMN('S-3'!C$5),FALSE)),"") | E16: =IFERROR(IF(ISBLANK(VLOOKUP($A16,'S-3'!$A:$K,COLUMN('S-3'!D$5),FALSE)),"",VLOOKUP($A16,'S-3'!$A:$K,COLUMN('S-3'!D$5),FALSE)),"") | F16: =IFERROR(IF(ISBLANK(VLOOKUP($A16,'S-3'!$A:$K,COLUMN('S-3'!E$5),FALSE)),"",VLOOKUP($A16,'S-3'!$A:$K,COLUMN('S-3'!E$5),FALSE)),"") | G16: =IFERROR(IF(ISBLANK(VLOOKUP($A16,'S-3'!$A:$K,COLUMN('S-3'!F$5),FALSE)),"",VLOOKUP($A16,'S-3'!$A:$K,COLUMN('S-3'!F$5),FALSE)),"") | H16: =IF(COUNT(C16:G16)=0,"",COUNT(C16:G16)) | I16: =IF(H16="","",SUM(C16:G16)) | J16: =IF(H16="","",I16/H16) | K16: =EDATE(K15,1) -> 694175 | L16: Agosto | M16: =IFERROR(IF(ISBLANK(VLOOKUP($K16,'S-3'!$A:$K,COLUMN('S-3'!B$5),FALSE)),"",VLOOKUP($K16,'S-3'!$A:$K,COLUMN('S-3'!B$5),FALSE)),"") | N16: =IFERROR(IF(ISBLANK(VLOOKUP($K16,'S-3'!$A:$K,COLUMN('S-3'!C$5),FALSE)),"",VLOOKUP($K16,'S-3'!$A:$K,COLUMN('S-3'!C$5),FALSE)),"") | O16: =IFERROR(IF(ISBLANK(VLOOKUP($K16,'S-3'!$A:$K,COLUMN('S-3'!D$5),FALSE)),"",VLOOKUP($K16,'S-3'!$A:$K,COLUMN('S-3'!D$5),FALSE)),"") | P16: =IFERROR(IF(ISBLANK(VLOOKUP($K16,'S-3'!$A:$K,COLUMN('S-3'!E$5),FALSE)),"",VLOOKUP($K16,'S-3'!$A:$K,COLUMN('S-3'!E$5),FALSE)),"") | Q16: =IFERROR(IF(ISBLANK(VLOOKUP($K16,'S-3'!$A:$K,COLUMN('S-3'!F$5),FALSE)),"",VLOOKUP($K16,'S-3'!$A:$K,COLUMN('S-3'!F$5),FALSE)),"") | R16: =IF(COUNT(M16:Q16)=0,"",COUNT(M16:Q16)) | S16: =IF(R16="","",SUM(M16:Q16)) | T16: =IF(R16="","",S16/R16)
B17: Promedio de asistencia mensual | J17: =AVERAGE(J5:J16) -> #DIV/0! | L17: Promedio de asistencia mensual | T17: =AVERAGE(T5:T16) -> #DIV/0!
B19: Reunión del fin de semana
B20: Año de servicio | C20: Primera Semana | D20: Segunda Semana | E20: Tercera Semana | F20: Cuarta Semana | G20: Quinta Semana | H20: Número de reuniones | I20: Asistencia total | J20: Promedio de asistencia semanal | L20: Año de servicio | M20: Primera Semana | N20: Segunda Semana | O20: Tercera Semana | P20: Cuarta Semana | Q20: Quinta Semana | R20: Número de reuniones | S20: Asistencia total | T20: Promedio de asistencia semanal
B21: =B4 -> 1899 | L21: =L4 -> 1900
A22: =DATE(B21-1,9,1) -> 693476 | B22: Septiembre | C22: =IFERROR(IF(ISBLANK(VLOOKUP($A22,'S-3'!$A:$K,COLUMN('S-3'!G$5),FALSE)),"",VLOOKUP($A22,'S-3'!$A:$K,COLUMN('S-3'!G$5),FALSE)),"") | D22: =IFERROR(IF(ISBLANK(VLOOKUP($A22,'S-3'!$A:$K,COLUMN('S-3'!H$5),FALSE)),"",VLOOKUP($A22,'S-3'!$A:$K,COLUMN('S-3'!H$5),FALSE)),"") | E22: =IFERROR(IF(ISBLANK(VLOOKUP($A22,'S-3'!$A:$K,COLUMN('S-3'!I$5),FALSE)),"",VLOOKUP($A22,'S-3'!$A:$K,COLUMN('S-3'!I$5),FALSE)),"") | F22: =IFERROR(IF(ISBLANK(VLOOKUP($A22,'S-3'!$A:$K,COLUMN('S-3'!J$5),FALSE)),"",VLOOKUP($A22,'S-3'!$A:$K,COLUMN('S-3'!J$5),FALSE)),"") | G22: =IFERROR(IF(ISBLANK(VLOOKUP($A22,'S-3'!$A:$K,COLUMN('S-3'!K$5),FALSE)),"",VLOOKUP($A22,'S-3'!$A:$K,COLUMN('S-3'!K$5),FALSE)),"") | H22: =IF(COUNT(C22:G22)=0,"",COUNT(C22:G22)) | I22: =IF(H22="","",SUM(C22:G22)) | J22: =IF(H22="","",I22/H22) | K22: =DATE(L21-1,9,1) -> 693841 | L22: Septiembre | M22: =IFERROR(IF(ISBLANK(VLOOKUP($K22,'S-3'!$A:$K,COLUMN('S-3'!G$5),FALSE)),"",VLOOKUP($K22,'S-3'!$A:$K,COLUMN('S-3'!G$5),FALSE)),"") | N22: =IFERROR(IF(ISBLANK(VLOOKUP($K22,'S-3'!$A:$K,COLUMN('S-3'!H$5),FALSE)),"",VLOOKUP($K22,'S-3'!$A:$K,COLUMN('S-3'!H$5),FALSE)),"") | O22: =IFERROR(IF(ISBLANK(VLOOKUP($K22,'S-3'!$A:$K,COLUMN('S-3'!I$5),FALSE)),"",VLOOKUP($K22,'S-3'!$A:$K,COLUMN('S-3'!I$5),FALSE)),"") | P22: =IFERROR(IF(ISBLANK(VLOOKUP($K22,'S-3'!$A:$K,COLUMN('S-3'!J$5),FALSE)),"",VLOOKUP($K22,'S-3'!$A:$K,COLUMN('S-3'!J$5),FALSE)),"") | Q22: =IFERROR(IF(ISBLANK(VLOOKUP($K22,'S-3'!$A:$K,COLUMN('S-3'!K$5),FALSE)),"",VLOOKUP($K22,'S-3'!$A:$K,COLUMN('S-3'!K$5),FALSE)),"") | R22: =IF(COUNT(M22:Q22)=0,"",COUNT(M22:Q22)) | S22: =IF(R22="","",SUM(M22:Q22)) | T22: =IF(R22="","",S22/R22)
A23: =EDATE(A22,1) -> 693506 | B23: Octubre | C23: =IFERROR(IF(ISBLANK(VLOOKUP($A23,'S-3'!$A:$K,COLUMN('S-3'!G$5),FALSE)),"",VLOOKUP($A23,'S-3'!$A:$K,COLUMN('S-3'!G$5),FALSE)),"") | D23: =IFERROR(IF(ISBLANK(VLOOKUP($A23,'S-3'!$A:$K,COLUMN('S-3'!H$5),FALSE)),"",VLOOKUP($A23,'S-3'!$A:$K,COLUMN('S-3'!H$5),FALSE)),"") | E23: =IFERROR(IF(ISBLANK(VLOOKUP($A23,'S-3'!$A:$K,COLUMN('S-3'!I$5),FALSE)),"",VLOOKUP($A23,'S-3'!$A:$K,COLUMN('S-3'!I$5),FALSE)),"") | F23: =IFERROR(IF(ISBLANK(VLOOKUP($A23,'S-3'!$A:$K,COLUMN('S-3'!J$5),FALSE)),"",VLOOKUP($A23,'S-3'!$A:$K,COLUMN('S-3'!J$5),FALSE)),"") | G23: =IFERROR(IF(ISBLANK(VLOOKUP($A23,'S-3'!$A:$K,COLUMN('S-3'!K$5),FALSE)),"",VLOOKUP($A23,'S-3'!$A:$K,COLUMN('S-3'!K$5),FALSE)),"") | H23: =IF(COUNT(C23:G23)=0,"",COUNT(C23:G23)) | I23: =IF(H23="","",SUM(C23:G23)) | J23: =IF(H23="","",I23/H23) | K23: =EDATE(K22,1) -> 693871 | L23: Octubre | M23: =IFERROR(IF(ISBLANK(VLOOKUP($K23,'S-3'!$A:$K,COLUMN('S-3'!G$5),FALSE)),"",VLOOKUP($K23,'S-3'!$A:$K,COLUMN('S-3'!G$5),FALSE)),"") | N23: =IFERROR(IF(ISBLANK(VLOOKUP($K23,'S-3'!$A:$K,COLUMN('S-3'!H$5),FALSE)),"",VLOOKUP($K23,'S-3'!$A:$K,COLUMN('S-3'!H$5),FALSE)),"") | O23: =IFERROR(IF(ISBLANK(VLOOKUP($K23,'S-3'!$A:$K,COLUMN('S-3'!I$5),FALSE)),"",VLOOKUP($K23,'S-3'!$A:$K,COLUMN('S-3'!I$5),FALSE)),"") | P23: =IFERROR(IF(ISBLANK(VLOOKUP($K23,'S-3'!$A:$K,COLUMN('S-3'!J$5),FALSE)),"",VLOOKUP($K23,'S-3'!$A:$K,COLUMN('S-3'!J$5),FALSE)),"") | Q23: =IFERROR(IF(ISBLANK(VLOOKUP($K23,'S-3'!$A:$K,COLUMN('S-3'!K$5),FALSE)),"",VLOOKUP($K23,'S-3'!$A:$K,COLUMN('S-3'!K$5),FALSE)),"") | R23: =IF(COUNT(M23:Q23)=0,"",COUNT(M23:Q23)) | S23: =IF(R23="","",SUM(M23:Q23)) | T23: =IF(R23="","",S23/R23)
A24: =EDATE(A23,1) -> 693537 | B24: Noviembre | C24: =IFERROR(IF(ISBLANK(VLOOKUP($A24,'S-3'!$A:$K,COLUMN('S-3'!G$5),FALSE)),"",VLOOKUP($A24,'S-3'!$A:$K,COLUMN('S-3'!G$5),FALSE)),"") | D24: =IFERROR(IF(ISBLANK(VLOOKUP($A24,'S-3'!$A:$K,COLUMN('S-3'!H$5),FALSE)),"",VLOOKUP($A24,'S-3'!$A:$K,COLUMN('S-3'!H$5),FALSE)),"") | E24: =IFERROR(IF(ISBLANK(VLOOKUP($A24,'S-3'!$A:$K,COLUMN('S-3'!I$5),FALSE)),"",VLOOKUP($A24,'S-3'!$A:$K,COLUMN('S-3'!I$5),FALSE)),"") | F24: =IFERROR(IF(ISBLANK(VLOOKUP($A24,'S-3'!$A:$K,COLUMN('S-3'!J$5),FALSE)),"",VLOOKUP($A24,'S-3'!$A:$K,COLUMN('S-3'!J$5),FALSE)),"") | G24: =IFERROR(IF(ISBLANK(VLOOKUP($A24,'S-3'!$A:$K,COLUMN('S-3'!K$5),FALSE)),"",VLOOKUP($A24,'S-3'!$A:$K,COLUMN('S-3'!K$5),FALSE)),"") | H24: =IF(COUNT(C24:G24)=0,"",COUNT(C24:G24)) | I24: =IF(H24="","",SUM(C24:G24)) | J24: =IF(H24="","",I24/H24) | K24: =EDATE(K23,1) -> 693902 | L24: Noviembre | M24: =IFERROR(IF(ISBLANK(VLOOKUP($K24,'S-3'!$A:$K,COLUMN('S-3'!G$5),FALSE)),"",VLOOKUP($K24,'S-3'!$A:$K,COLUMN('S-3'!G$5),FALSE)),"") | N24: =IFERROR(IF(ISBLANK(VLOOKUP($K24,'S-3'!$A:$K,COLUMN('S-3'!H$5),FALSE)),"",VLOOKUP($K24,'S-3'!$A:$K,COLUMN('S-3'!H$5),FALSE)),"") | O24: =IFERROR(IF(ISBLANK(VLOOKUP($K24,'S-3'!$A:$K,COLUMN('S-3'!I$5),FALSE)),"",VLOOKUP($K24,'S-3'!$A:$K,COLUMN('S-3'!I$5),FALSE)),"") | P24: =IFERROR(IF(ISBLANK(VLOOKUP($K24,'S-3'!$A:$K,COLUMN('S-3'!J$5),FALSE)),"",VLOOKUP($K24,'S-3'!$A:$K,COLUMN('S-3'!J$5),FALSE)),"") | Q24: =IFERROR(IF(ISBLANK(VLOOKUP($K24,'S-3'!$A:$K,COLUMN('S-3'!K$5),FALSE)),"",VLOOKUP($K24,'S-3'!$A:$K,COLUMN('S-3'!K$5),FALSE)),"") | R24: =IF(COUNT(M24:Q24)=0,"",COUNT(M24:Q24)) | S24: =IF(R24="","",SUM(M24:Q24)) | T24: =IF(R24="","",S24/R24)
A25: =EDATE(A24,1) -> 693567 | B25: Diciembre | C25: =IFERROR(IF(ISBLANK(VLOOKUP($A25,'S-3'!$A:$K,COLUMN('S-3'!G$5),FALSE)),"",VLOOKUP($A25,'S-3'!$A:$K,COLUMN('S-3'!G$5),FALSE)),"") | D25: =IFERROR(IF(ISBLANK(VLOOKUP($A25,'S-3'!$A:$K,COLUMN('S-3'!H$5),FALSE)),"",VLOOKUP($A25,'S-3'!$A:$K,COLUMN('S-3'!H$5),FALSE)),"") | E25: =IFERROR(IF(ISBLANK(VLOOKUP($A25,'S-3'!$A:$K,COLUMN('S-3'!I$5),FALSE)),"",VLOOKUP($A25,'S-3'!$A:$K,COLUMN('S-3'!I$5),FALSE)),"") | F25: =IFERROR(IF(ISBLANK(VLOOKUP($A25,'S-3'!$A:$K,COLUMN('S-3'!J$5),FALSE)),"",VLOOKUP($A25,'S-3'!$A:$K,COLUMN('S-3'!J$5),FALSE)),"") | G25: =IFERROR(IF(ISBLANK(VLOOKUP($A25,'S-3'!$A:$K,COLUMN('S-3'!K$5),FALSE)),"",VLOOKUP($A25,'S-3'!$A:$K,COLUMN('S-3'!K$5),FALSE)),"") | H25: =IF(COUNT(C25:G25)=0,"",COUNT(C25:G25)) | I25: =IF(H25="","",SUM(C25:G25)) | J25: =IF(H25="","",I25/H25) | K25: =EDATE(K24,1) -> 693932 | L25: Diciembre | M25: =IFERROR(IF(ISBLANK(VLOOKUP($K25,'S-3'!$A:$K,COLUMN('S-3'!G$5),FALSE)),"",VLOOKUP($K25,'S-3'!$A:$K,COLUMN('S-3'!G$5),FALSE)),"") | N25: =IFERROR(IF(ISBLANK(VLOOKUP($K25,'S-3'!$A:$K,COLUMN('S-3'!H$5),FALSE)),"",VLOOKUP($K25,'S-3'!$A:$K,COLUMN('S-3'!H$5),FALSE)),"") | O25: =IFERROR(IF(ISBLANK(VLOOKUP($K25,'S-3'!$A:$K,COLUMN('S-3'!I$5),FALSE)),"",VLOOKUP($K25,'S-3'!$A:$K,COLUMN('S-3'!I$5),FALSE)),"") | P25: =IFERROR(IF(ISBLANK(VLOOKUP($K25,'S-3'!$A:$K,COLUMN('S-3'!J$5),FALSE)),"",VLOOKUP($K25,'S-3'!$A:$K,COLUMN('S-3'!J$5),FALSE)),"") | Q25: =IFERROR(IF(ISBLANK(VLOOKUP($K25,'S-3'!$A:$K,COLUMN('S-3'!K$5),FALSE)),"",VLOOKUP($K25,'S-3'!$A:$K,COLUMN('S-3'!K$5),FALSE)),"") | R25: =IF(COUNT(M25:Q25)=0,"",COUNT(M25:Q25)) | S25: =IF(R25="","",SUM(M25:Q25)) | T25: =IF(R25="","",S25/R25)
A26: =EDATE(A25,1) -> 693598 | B26: Enero | C26: =IFERROR(IF(ISBLANK(VLOOKUP($A26,'S-3'!$A:$K,COLUMN('S-3'!G$5),FALSE)),"",VLOOKUP($A26,'S-3'!$A:$K,COLUMN('S-3'!G$5),FALSE)),"") | D26: =IFERROR(IF(ISBLANK(VLOOKUP($A26,'S-3'!$A:$K,COLUMN('S-3'!H$5),FALSE)),"",VLOOKUP($A26,'S-3'!$A:$K,COLUMN('S-3'!H$5),FALSE)),"") | E26: =IFERROR(IF(ISBLANK(VLOOKUP($A26,'S-3'!$A:$K,COLUMN('S-3'!I$5),FALSE)),"",VLOOKUP($A26,'S-3'!$A:$K,COLUMN('S-3'!I$5),FALSE)),"") | F26: =IFERROR(IF(ISBLANK(VLOOKUP($A26,'S-3'!$A:$K,COLUMN('S-3'!J$5),FALSE)),"",VLOOKUP($A26,'S-3'!$A:$K,COLUMN('S-3'!J$5),FALSE)),"") | G26: =IFERROR(IF(ISBLANK(VLOOKUP($A26,'S-3'!$A:$K,COLUMN('S-3'!K$5),FALSE)),"",VLOOKUP($A26,'S-3'!$A:$K,COLUMN('S-3'!K$5),FALSE)),"") | H26: =IF(COUNT(C26:G26)=0,"",COUNT(C26:G26)) | I26: =IF(H26="","",SUM(C26:G26)) | J26: =IF(H26="","",I26/H26) | K26: =EDATE(K25,1) -> 693963 | L26: Enero | M26: =IFERROR(IF(ISBLANK(VLOOKUP($K26,'S-3'!$A:$K,COLUMN('S-3'!G$5),FALSE)),"",VLOOKUP($K26,'S-3'!$A:$K,COLUMN('S-3'!G$5),FALSE)),"") | N26: =IFERROR(IF(ISBLANK(VLOOKUP($K26,'S-3'!$A:$K,COLUMN('S-3'!H$5),FALSE)),"",VLOOKUP($K26,'S-3'!$A:$K,COLUMN('S-3'!H$5),FALSE)),"") | O26: =IFERROR(IF(ISBLANK(VLOOKUP($K26,'S-3'!$A:$K,COLUMN('S-3'!I$5),FALSE)),"",VLOOKUP($K26,'S-3'!$A:$K,COLUMN('S-3'!I$5),FALSE)),"") | P26: =IFERROR(IF(ISBLANK(VLOOKUP($K26,'S-3'!$A:$K,COLUMN('S-3'!J$5),FALSE)),"",VLOOKUP($K26,'S-3'!$A:$K,COLUMN('S-3'!J$5),FALSE)),"") | Q26: =IFERROR(IF(ISBLANK(VLOOKUP($K26,'S-3'!$A:$K,COLUMN('S-3'!K$5),FALSE)),"",VLOOKUP($K26,'S-3'!$A:$K,COLUMN('S-3'!K$5),FALSE)),"") | R26: =IF(COUNT(M26:Q26)=0,"",COUNT(M26:Q26)) | S26: =IF(R26="","",SUM(M26:Q26)) | T26: =IF(R26="","",S26/R26)
A27: =EDATE(A26,1) -> 693629 | B27: Febrero | C27: =IFERROR(IF(ISBLANK(VLOOKUP($A27,'S-3'!$A:$K,COLUMN('S-3'!G$5),FALSE)),"",VLOOKUP($A27,'S-3'!$A:$K,COLUMN('S-3'!G$5),FALSE)),"") | D27: =IFERROR(IF(ISBLANK(VLOOKUP($A27,'S-3'!$A:$K,COLUMN('S-3'!H$5),FALSE)),"",VLOOKUP($A27,'S-3'!$A:$K,COLUMN('S-3'!H$5),FALSE)),"") | E27: =IFERROR(IF(ISBLANK(VLOOKUP($A27,'S-3'!$A:$K,COLUMN('S-3'!I$5),FALSE)),"",VLOOKUP($A27,'S-3'!$A:$K,COLUMN('S-3'!I$5),FALSE)),"") | F27: =IFERROR(IF(ISBLANK(VLOOKUP($A27,'S-3'!$A:$K,COLUMN('S-3'!J$5),FALSE)),"",VLOOKUP($A27,'S-3'!$A:$K,COLUMN('S-3'!J$5),FALSE)),"") | G27: =IFERROR(IF(ISBLANK(VLOOKUP($A27,'S-3'!$A:$K,COLUMN('S-3'!K$5),FALSE)),"",VLOOKUP($A27,'S-3'!$A:$K,COLUMN('S-3'!K$5),FALSE)),"") | H27: =IF(COUNT(C27:G27)=0,"",COUNT(C27:G27)) | I27: =IF(H27="","",SUM(C27:G27)) | J27: =IF(H27="","",I27/H27) | K27: =EDATE(K26,1) -> 693994 | L27: Febrero | M27: =IFERROR(IF(ISBLANK(VLOOKUP($K27,'S-3'!$A:$K,COLUMN('S-3'!G$5),FALSE)),"",VLOOKUP($K27,'S-3'!$A:$K,COLUMN('S-3'!G$5),FALSE)),"") | N27: =IFERROR(IF(ISBLANK(VLOOKUP($K27,'S-3'!$A:$K,COLUMN('S-3'!H$5),FALSE)),"",VLOOKUP($K27,'S-3'!$A:$K,COLUMN('S-3'!H$5),FALSE)),"") | O27: =IFERROR(IF(ISBLANK(VLOOKUP($K27,'S-3'!$A:$K,COLUMN('S-3'!I$5),FALSE)),"",VLOOKUP($K27,'S-3'!$A:$K,COLUMN('S-3'!I$5),FALSE)),"") | P27: =IFERROR(IF(ISBLANK(VLOOKUP($K27,'S-3'!$A:$K,COLUMN('S-3'!J$5),FALSE)),"",VLOOKUP($K27,'S-3'!$A:$K,COLUMN('S-3'!J$5),FALSE)),"") | Q27: =IFERROR(IF(ISBLANK(VLOOKUP($K27,'S-3'!$A:$K,COLUMN('S-3'!K$5),FALSE)),"",VLOOKUP($K27,'S-3'!$A:$K,COLUMN('S-3'!K$5),FALSE)),"") | R27: =IF(COUNT(M27:Q27)=0,"",COUNT(M27:Q27)) | S27: =IF(R27="","",SUM(M27:Q27)) | T27: =IF(R27="","",S27/R27)
A28: =EDATE(A27,1) -> 693657 | B28: Marzo | C28: =IFERROR(IF(ISBLANK(VLOOKUP($A28,'S-3'!$A:$K,COLUMN('S-3'!G$5),FALSE)),"",VLOOKUP($A28,'S-3'!$A:$K,COLUMN('S-3'!G$5),FALSE)),"") | D28: =IFERROR(IF(ISBLANK(VLOOKUP($A28,'S-3'!$A:$K,COLUMN('S-3'!H$5),FALSE)),"",VLOOKUP($A28,'S-3'!$A:$K,COLUMN('S-3'!H$5),FALSE)),"") | E28: =IFERROR(IF(ISBLANK(VLOOKUP($A28,'S-3'!$A:$K,COLUMN('S-3'!I$5),FALSE)),"",VLOOKUP($A28,'S-3'!$A:$K,COLUMN('S-3'!I$5),FALSE)),"") | F28: =IFERROR(IF(ISBLANK(VLOOKUP($A28,'S-3'!$A:$K,COLUMN('S-3'!J$5),FALSE)),"",VLOOKUP($A28,'S-3'!$A:$K,COLUMN('S-3'!J$5),FALSE)),"") | G28: =IFERROR(IF(ISBLANK(VLOOKUP($A28,'S-3'!$A:$K,COLUMN('S-3'!K$5),FALSE)),"",VLOOKUP($A28,'S-3'!$A:$K,COLUMN('S-3'!K$5),FALSE)),"") | H28: =IF(COUNT(C28:G28)=0,"",COUNT(C28:G28)) | I28: =IF(H28="","",SUM(C28:G28)) | J28: =IF(H28="","",I28/H28) | K28: =EDATE(K27,1) -> 694022 | L28: Marzo | M28: =IFERROR(IF(ISBLANK(VLOOKUP($K28,'S-3'!$A:$K,COLUMN('S-3'!G$5),FALSE)),"",VLOOKUP($K28,'S-3'!$A:$K,COLUMN('S-3'!G$5),FALSE)),"") | N28: =IFERROR(IF(ISBLANK(VLOOKUP($K28,'S-3'!$A:$K,COLUMN('S-3'!H$5),FALSE)),"",VLOOKUP($K28,'S-3'!$A:$K,COLUMN('S-3'!H$5),FALSE)),"") | O28: =IFERROR(IF(ISBLANK(VLOOKUP($K28,'S-3'!$A:$K,COLUMN('S-3'!I$5),FALSE)),"",VLOOKUP($K28,'S-3'!$A:$K,COLUMN('S-3'!I$5),FALSE)),"") | P28: =IFERROR(IF(ISBLANK(VLOOKUP($K28,'S-3'!$A:$K,COLUMN('S-3'!J$5),FALSE)),"",VLOOKUP($K28,'S-3'!$A:$K,COLUMN('S-3'!J$5),FALSE)),"") | Q28: =IFERROR(IF(ISBLANK(VLOOKUP($K28,'S-3'!$A:$K,COLUMN('S-3'!K$5),FALSE)),"",VLOOKUP($K28,'S-3'!$A:$K,COLUMN('S-3'!K$5),FALSE)),"") | R28: =IF(COUNT(M28:Q28)=0,"",COUNT(M28:Q28)) | S28: =IF(R28="","",SUM(M28:Q28)) | T28: =IF(R28="","",S28/R28)
A29: =EDATE(A28,1) -> 693688 | B29: Abril | C29: =IFERROR(IF(ISBLANK(VLOOKUP($A29,'S-3'!$A:$K,COLUMN('S-3'!G$5),FALSE)),"",VLOOKUP($A29,'S-3'!$A:$K,COLUMN('S-3'!G$5),FALSE)),"") | D29: =IFERROR(IF(ISBLANK(VLOOKUP($A29,'S-3'!$A:$K,COLUMN('S-3'!H$5),FALSE)),"",VLOOKUP($A29,'S-3'!$A:$K,COLUMN('S-3'!H$5),FALSE)),"") | E29: =IFERROR(IF(ISBLANK(VLOOKUP($A29,'S-3'!$A:$K,COLUMN('S-3'!I$5),FALSE)),"",VLOOKUP($A29,'S-3'!$A:$K,COLUMN('S-3'!I$5),FALSE)),"") | F29: =IFERROR(IF(ISBLANK(VLOOKUP($A29,'S-3'!$A:$K,COLUMN('S-3'!J$5),FALSE)),"",VLOOKUP($A29,'S-3'!$A:$K,COLUMN('S-3'!J$5),FALSE)),"") | G29: =IFERROR(IF(ISBLANK(VLOOKUP($A29,'S-3'!$A:$K,COLUMN('S-3'!K$5),FALSE)),"",VLOOKUP($A29,'S-3'!$A:$K,COLUMN('S-3'!K$5),FALSE)),"") | H29: =IF(COUNT(C29:G29)=0,"",COUNT(C29:G29)) | I29: =IF(H29="","",SUM(C29:G29)) | J29: =IF(H29="","",I29/H29) | K29: =EDATE(K28,1) -> 694053 | L29: Abril | M29: =IFERROR(IF(ISBLANK(VLOOKUP($K29,'S-3'!$A:$K,COLUMN('S-3'!G$5),FALSE)),"",VLOOKUP($K29,'S-3'!$A:$K,COLUMN('S-3'!G$5),FALSE)),"") | N29: =IFERROR(IF(ISBLANK(VLOOKUP($K29,'S-3'!$A:$K,COLUMN('S-3'!H$5),FALSE)),"",VLOOKUP($K29,'S-3'!$A:$K,COLUMN('S-3'!H$5),FALSE)),"") | O29: =IFERROR(IF(ISBLANK(VLOOKUP($K29,'S-3'!$A:$K,COLUMN('S-3'!I$5),FALSE)),"",VLOOKUP($K29,'S-3'!$A:$K,COLUMN('S-3'!I$5),FALSE)),"") | P29: =IFERROR(IF(ISBLANK(VLOOKUP($K29,'S-3'!$A:$K,COLUMN('S-3'!J$5),FALSE)),"",VLOOKUP($K29,'S-3'!$A:$K,COLUMN('S-3'!J$5),FALSE)),"") | Q29: =IFERROR(IF(ISBLANK(VLOOKUP($K29,'S-3'!$A:$K,COLUMN('S-3'!K$5),FALSE)),"",VLOOKUP($K29,'S-3'!$A:$K,COLUMN('S-3'!K$5),FALSE)),"") | R29: =IF(COUNT(M29:Q29)=0,"",COUNT(M29:Q29)) | S29: =IF(R29="","",SUM(M29:Q29)) | T29: =IF(R29="","",S29/R29)
A30: =EDATE(A29,1) -> 693718 | B30: Mayo | C30: =IFERROR(IF(ISBLANK(VLOOKUP($A30,'S-3'!$A:$K,COLUMN('S-3'!G$5),FALSE)),"",VLOOKUP($A30,'S-3'!$A:$K,COLUMN('S-3'!G$5),FALSE)),"") | D30: =IFERROR(IF(ISBLANK(VLOOKUP($A30,'S-3'!$A:$K,COLUMN('S-3'!H$5),FALSE)),"",VLOOKUP($A30,'S-3'!$A:$K,COLUMN('S-3'!H$5),FALSE)),"") | E30: =IFERROR(IF(ISBLANK(VLOOKUP($A30,'S-3'!$A:$K,COLUMN('S-3'!I$5),FALSE)),"",VLOOKUP($A30,'S-3'!$A:$K,COLUMN('S-3'!I$5),FALSE)),"") | F30: =IFERROR(IF(ISBLANK(VLOOKUP($A30,'S-3'!$A:$K,COLUMN('S-3'!J$5),FALSE)),"",VLOOKUP($A30,'S-3'!$A:$K,COLUMN('S-3'!J$5),FALSE)),"") | G30: =IFERROR(IF(ISBLANK(VLOOKUP($A30,'S-3'!$A:$K,COLUMN('S-3'!K$5),FALSE)),"",VLOOKUP($A30,'S-3'!$A:$K,COLUMN('S-3'!K$5),FALSE)),"") | H30: =IF(COUNT(C30:G30)=0,"",COUNT(C30:G30)) | I30: =IF(H30="","",SUM(C30:G30)) | J30: =IF(H30="","",I30/H30) | K30: =EDATE(K29,1) -> 694083 | L30: Mayo | M30: =IFERROR(IF(ISBLANK(VLOOKUP($K30,'S-3'!$A:$K,COLUMN('S-3'!G$5),FALSE)),"",VLOOKUP($K30,'S-3'!$A:$K,COLUMN('S-3'!G$5),FALSE)),"") | N30: =IFERROR(IF(ISBLANK(VLOOKUP($K30,'S-3'!$A:$K,COLUMN('S-3'!H$5),FALSE)),"",VLOOKUP($K30,'S-3'!$A:$K,COLUMN('S-3'!H$5),FALSE)),"") | O30: =IFERROR(IF(ISBLANK(VLOOKUP($K30,'S-3'!$A:$K,COLUMN('S-3'!I$5),FALSE)),"",VLOOKUP($K30,'S-3'!$A:$K,COLUMN('S-3'!I$5),FALSE)),"") | P30: =IFERROR(IF(ISBLANK(VLOOKUP($K30,'S-3'!$A:$K,COLUMN('S-3'!J$5),FALSE)),"",VLOOKUP($K30,'S-3'!$A:$K,COLUMN('S-3'!J$5),FALSE)),"") | Q30: =IFERROR(IF(ISBLANK(VLOOKUP($K30,'S-3'!$A:$K,COLUMN('S-3'!K$5),FALSE)),"",VLOOKUP($K30,'S-3'!$A:$K,COLUMN('S-3'!K$5),FALSE)),"") | R30: =IF(COUNT(M30:Q30)=0,"",COUNT(M30:Q30)) | S30: =IF(R30="","",SUM(M30:Q30)) | T30: =IF(R30="","",S30/R30)
A31: =EDATE(A30,1) -> 693749 | B31: Junio | C31: =IFERROR(IF(ISBLANK(VLOOKUP($A31,'S-3'!$A:$K,COLUMN('S-3'!G$5),FALSE)),"",VLOOKUP($A31,'S-3'!$A:$K,COLUMN('S-3'!G$5),FALSE)),"") | D31: =IFERROR(IF(ISBLANK(VLOOKUP($A31,'S-3'!$A:$K,COLUMN('S-3'!H$5),FALSE)),"",VLOOKUP($A31,'S-3'!$A:$K,COLUMN('S-3'!H$5),FALSE)),"") | E31: =IFERROR(IF(ISBLANK(VLOOKUP($A31,'S-3'!$A:$K,COLUMN('S-3'!I$5),FALSE)),"",VLOOKUP($A31,'S-3'!$A:$K,COLUMN('S-3'!I$5),FALSE)),"") | F31: =IFERROR(IF(ISBLANK(VLOOKUP($A31,'S-3'!$A:$K,COLUMN('S-3'!J$5),FALSE)),"",VLOOKUP($A31,'S-3'!$A:$K,COLUMN('S-3'!J$5),FALSE)),"") | G31: =IFERROR(IF(ISBLANK(VLOOKUP($A31,'S-3'!$A:$K,COLUMN('S-3'!K$5),FALSE)),"",VLOOKUP($A31,'S-3'!$A:$K,COLUMN('S-3'!K$5),FALSE)),"") | H31: =IF(COUNT(C31:G31)=0,"",COUNT(C31:G31)) | I31: =IF(H31="","",SUM(C31:G31)) | J31: =IF(H31="","",I31/H31) | K31: =EDATE(K30,1) -> 694114 | L31: Junio | M31: =IFERROR(IF(ISBLANK(VLOOKUP($K31,'S-3'!$A:$K,COLUMN('S-3'!G$5),FALSE)),"",VLOOKUP($K31,'S-3'!$A:$K,COLUMN('S-3'!G$5),FALSE)),"") | N31: =IFERROR(IF(ISBLANK(VLOOKUP($K31,'S-3'!$A:$K,COLUMN('S-3'!H$5),FALSE)),"",VLOOKUP($K31,'S-3'!$A:$K,COLUMN('S-3'!H$5),FALSE)),"") | O31: =IFERROR(IF(ISBLANK(VLOOKUP($K31,'S-3'!$A:$K,COLUMN('S-3'!I$5),FALSE)),"",VLOOKUP($K31,'S-3'!$A:$K,COLUMN('S-3'!I$5),FALSE)),"") | P31: =IFERROR(IF(ISBLANK(VLOOKUP($K31,'S-3'!$A:$K,COLUMN('S-3'!J$5),FALSE)),"",VLOOKUP($K31,'S-3'!$A:$K,COLUMN('S-3'!J$5),FALSE)),"") | Q31: =IFERROR(IF(ISBLANK(VLOOKUP($K31,'S-3'!$A:$K,COLUMN('S-3'!K$5),FALSE)),"",VLOOKUP($K31,'S-3'!$A:$K,COLUMN('S-3'!K$5),FALSE)),"") | R31: =IF(COUNT(M31:Q31)=0,"",COUNT(M31:Q31)) | S31: =IF(R31="","",SUM(M31:Q31)) | T31: =IF(R31="","",S31/R31)
A32: =EDATE(A31,1) -> 693779 | B32: Julio | C32: =IFERROR(IF(ISBLANK(VLOOKUP($A32,'S-3'!$A:$K,COLUMN('S-3'!G$5),FALSE)),"",VLOOKUP($A32,'S-3'!$A:$K,COLUMN('S-3'!G$5),FALSE)),"") | D32: =IFERROR(IF(ISBLANK(VLOOKUP($A32,'S-3'!$A:$K,COLUMN('S-3'!H$5),FALSE)),"",VLOOKUP($A32,'S-3'!$A:$K,COLUMN('S-3'!H$5),FALSE)),"") | E32: =IFERROR(IF(ISBLANK(VLOOKUP($A32,'S-3'!$A:$K,COLUMN('S-3'!I$5),FALSE)),"",VLOOKUP($A32,'S-3'!$A:$K,COLUMN('S-3'!I$5),FALSE)),"") | F32: =IFERROR(IF(ISBLANK(VLOOKUP($A32,'S-3'!$A:$K,COLUMN('S-3'!J$5),FALSE)),"",VLOOKUP($A32,'S-3'!$A:$K,COLUMN('S-3'!J$5),FALSE)),"") | G32: =IFERROR(IF(ISBLANK(VLOOKUP($A32,'S-3'!$A:$K,COLUMN('S-3'!K$5),FALSE)),"",VLOOKUP($A32,'S-3'!$A:$K,COLUMN('S-3'!K$5),FALSE)),"") | H32: =IF(COUNT(C32:G32)=0,"",COUNT(C32:G32)) | I32: =IF(H32="","",SUM(C32:G32)) | J32: =IF(H32="","",I32/H32) | K32: =EDATE(K31,1) -> 694144 | L32: Julio | M32: =IFERROR(IF(ISBLANK(VLOOKUP($K32,'S-3'!$A:$K,COLUMN('S-3'!G$5),FALSE)),"",VLOOKUP($K32,'S-3'!$A:$K,COLUMN('S-3'!G$5),FALSE)),"") | N32: =IFERROR(IF(ISBLANK(VLOOKUP($K32,'S-3'!$A:$K,COLUMN('S-3'!H$5),FALSE)),"",VLOOKUP($K32,'S-3'!$A:$K,COLUMN('S-3'!H$5),FALSE)),"") | O32: =IFERROR(IF(ISBLANK(VLOOKUP($K32,'S-3'!$A:$K,COLUMN('S-3'!I$5),FALSE)),"",VLOOKUP($K32,'S-3'!$A:$K,COLUMN('S-3'!I$5),FALSE)),"") | P32: =IFERROR(IF(ISBLANK(VLOOKUP($K32,'S-3'!$A:$K,COLUMN('S-3'!J$5),FALSE)),"",VLOOKUP($K32,'S-3'!$A:$K,COLUMN('S-3'!J$5),FALSE)),"") | Q32: =IFERROR(IF(ISBLANK(VLOOKUP($K32,'S-3'!$A:$K,COLUMN('S-3'!K$5),FALSE)),"",VLOOKUP($K32,'S-3'!$A:$K,COLUMN('S-3'!K$5),FALSE)),"") | R32: =IF(COUNT(M32:Q32)=0,"",COUNT(M32:Q32)) | S32: =IF(R32="","",SUM(M32:Q32)) | T32: =IF(R32="","",S32/R32)
A33: =EDATE(A32,1) -> 693810 | B33: Agosto | C33: =IFERROR(IF(ISBLANK(VLOOKUP($A33,'S-3'!$A:$K,COLUMN('S-3'!G$5),FALSE)),"",VLOOKUP($A33,'S-3'!$A:$K,COLUMN('S-3'!G$5),FALSE)),"") | D33: =IFERROR(IF(ISBLANK(VLOOKUP($A33,'S-3'!$A:$K,COLUMN('S-3'!H$5),FALSE)),"",VLOOKUP($A33,'S-3'!$A:$K,COLUMN('S-3'!H$5),FALSE)),"") | E33: =IFERROR(IF(ISBLANK(VLOOKUP($A33,'S-3'!$A:$K,COLUMN('S-3'!I$5),FALSE)),"",VLOOKUP($A33,'S-3'!$A:$K,COLUMN('S-3'!I$5),FALSE)),"") | F33: =IFERROR(IF(ISBLANK(VLOOKUP($A33,'S-3'!$A:$K,COLUMN('S-3'!J$5),FALSE)),"",VLOOKUP($A33,'S-3'!$A:$K,COLUMN('S-3'!J$5),FALSE)),"") | G33: =IFERROR(IF(ISBLANK(VLOOKUP($A33,'S-3'!$A:$K,COLUMN('S-3'!K$5),FALSE)),"",VLOOKUP($A33,'S-3'!$A:$K,COLUMN('S-3'!K$5),FALSE)),"") | H33: =IF(COUNT(C33:G33)=0,"",COUNT(C33:G33)) | I33: =IF(H33="","",SUM(C33:G33)) | J33: =IF(H33="","",I33/H33) | K33: =EDATE(K32,1) -> 694175 | L33: Agosto | M33: =IFERROR(IF(ISBLANK(VLOOKUP($K33,'S-3'!$A:$K,COLUMN('S-3'!G$5),FALSE)),"",VLOOKUP($K33,'S-3'!$A:$K,COLUMN('S-3'!G$5),FALSE)),"") | N33: =IFERROR(IF(ISBLANK(VLOOKUP($K33,'S-3'!$A:$K,COLUMN('S-3'!H$5),FALSE)),"",VLOOKUP($K33,'S-3'!$A:$K,COLUMN('S-3'!H$5),FALSE)),"") | O33: =IFERROR(IF(ISBLANK(VLOOKUP($K33,'S-3'!$A:$K,COLUMN('S-3'!I$5),FALSE)),"",VLOOKUP($K33,'S-3'!$A:$K,COLUMN('S-3'!I$5),FALSE)),"") | P33: =IFERROR(IF(ISBLANK(VLOOKUP($K33,'S-3'!$A:$K,COLUMN('S-3'!J$5),FALSE)),"",VLOOKUP($K33,'S-3'!$A:$K,COLUMN('S-3'!J$5),FALSE)),"") | Q33: =IFERROR(IF(ISBLANK(VLOOKUP($K33,'S-3'!$A:$K,COLUMN('S-3'!K$5),FALSE)),"",VLOOKUP($K33,'S-3'!$A:$K,COLUMN('S-3'!K$5),FALSE)),"") | R33: =IF(COUNT(M33:Q33)=0,"",COUNT(M33:Q33)) | S33: =IF(R33="","",SUM(M33:Q33)) | T33: =IF(R33="","",S33/R33)
B34: Promedio de asistencia mensual | J34: =AVERAGE(J22:J33) -> #DIV/0! | L34: Promedio de asistencia mensual | T34: =AVERAGE(T22:T33) -> #DIV/0!
B36: S-88-S 12/18

Sheet S-3
B1: Asistencias
B2: ES | G2: FS
B3: 1 | C3: 2 | D3: 3 | E3: 4 | F3: 5 | G3: 1 | H3: 2 | I3: 3 | J3: 4 | K3: 5
B4: Reunión de entresemana | G4: Reunión del fin de semana
A5: Mes | B5: Primera Semana | C5: Segunda Semana | D5: Tercera Semana | E5: Cuarta Semana | F5: Quinta Semana | G5: Primera Semana | H5: Segunda Semana | I5: Tercera Semana | J5: Cuarta Semana | K5: Quinta Semana
A6: 45536 | B6: =IFERROR(IF(ISBLANK(VLOOKUP(TEXT($A6,"aaaa-mm")&"_"&$B$2&"_"&B$3,tblAsistencias[],6,FALSE)), "", VLOOKUP(TEXT($A6,"aaaa-mm")&"_"&$B$2&"_"&B$3,tblAsistencias[],6,FALSE)), "") | C6: =IFERROR(IF(ISBLANK(VLOOKUP(TEXT($A6,"aaaa-mm")&"_"&$B$2&"_"&C$3,tblAsistencias[],6,FALSE)), "", VLOOKUP(TEXT($A6,"aaaa-mm")&"_"&$B$2&"_"&C$3,tblAsistencias[],6,FALSE)), "") | D6: =IFERROR(IF(ISBLANK(VLOOKUP(TEXT($A6,"aaaa-mm")&"_"&$B$2&"_"&D$3,tblAsistencias[],6,FALSE)), "", VLOOKUP(TEXT($A6,"aaaa-mm")&"_"&$B$2&"_"&D$3,tblAsistencias[],6,FALSE)), "") | E6: =IFERROR(IF(ISBLANK(VLOOKUP(TEXT($A6,"aaaa-mm")&"_"&$B$2&"_"&E$3,tblAsistencias[],6,FALSE)), "", VLOOKUP(TEXT($A6,"aaaa-mm")&"_"&$B$2&"_"&E$3,tblAsistencias[],6,FALSE)), "") | F6: =IFERROR(IF(ISBLANK(VLOOKUP(TEXT($A6,"aaaa-mm")&"_"&$B$2&"_"&F$3,tblAsistencias[],6,FALSE)), "", VLOOKUP(TEXT($A6,"aaaa-mm")&"_"&$B$2&"_"&F$3,tblAsistencias[],6,FALSE)), "") | G6: =IFERROR(IF(ISBLANK(VLOOKUP(TEXT($A6,"aaaa-mm")&"_"&$G$2&"_"&G$3,tblAsistencias[],6,FALSE)), "", VLOOKUP(TEXT($A6,"aaaa-mm")&"_"&$G$2&"_"&G$3,tblAsistencias[],6,FALSE)), "") | H6: =IFERROR(IF(ISBLANK(VLOOKUP(TEXT($A6,"aaaa-mm")&"_"&$G$2&"_"&H$3,tblAsistencias[],6,FALSE)), "", VLOOKUP(TEXT($A6,"aaaa-mm")&"_"&$G$2&"_"&H$3,tblAsistencias[],6,FALSE)), "") | I6: =IFERROR(IF(ISBLANK(VLOOKUP(TEXT($A6,"aaaa-mm")&"_"&$G$2&"_"&I$3,tblAsistencias[],6,FALSE)), "", VLOOKUP(TEXT($A6,"aaaa-mm")&"_"&$G$2&"_"&I$3,tblAsistencias[],6,FALSE)), "") | J6: =IFERROR(IF(ISBLANK(VLOOKUP(TEXT($A6,"aaaa-mm")&"_"&$G$2&"_"&J$3,tblAsistencias[],6,FALSE)), "", VLOOKUP(TEXT($A6,"aaaa-mm")&"_"&$G$2&"_"&J$3,tblAsistencias[],6,FALSE)), "") | K6: =IFERROR(IF(ISBLANK(VLOOKUP(TEXT($A6,"aaaa-mm")&"_"&$G$2&"_"&K$3,tblAsistencias[],6,FALSE)), "", VLOOKUP(TEXT($A6,"aaaa-mm")&"_"&$G$2&"_"&K$3,tblAsistencias[],6,FALSE)), "")
A7: 45566 | B7: =IFERROR(IF(ISBLANK(VLOOKUP(TEXT($A7,"aaaa-mm")&"_"&$B$2&"_"&B$3,tblAsistencias[],6,FALSE)), "", VLOOKUP(TEXT($A7,"aaaa-mm")&"_"&$B$2&"_"&B$3,tblAsistencias[],6,FALSE)), "") | C7: =IFERROR(IF(ISBLANK(VLOOKUP(TEXT($A7,"aaaa-mm")&"_"&$B$2&"_"&C$3,tblAsistencias[],6,FALSE)), "", VLOOKUP(TEXT($A7,"aaaa-mm")&"_"&$B$2&"_"&C$3,tblAsistencias[],6,FALSE)), "") | D7: =IFERROR(IF(ISBLANK(VLOOKUP(TEXT($A7,"aaaa-mm")&"_"&$B$2&"_"&D$3,tblAsistencias[],6,FALSE)), "", VLOOKUP(TEXT($A7,"aaaa-mm")&"_"&$B$2&"_"&D$3,tblAsistencias[],6,FALSE)), "") | E7: =IFERROR(IF(ISBLANK(VLOOKUP(TEXT($A7,"aaaa-mm")&"_"&$B$2&"_"&E$3,tblAsistencias[],6,FALSE)), "", VLOOKUP(TEXT($A7,"aaaa-mm")&"_"&$B$2&"_"&E$3,tblAsistencias[],6,FALSE)), "") | F7: =IFERROR(IF(ISBLANK(VLOOKUP(TEXT($A7,"aaaa-mm")&"_"&$B$2&"_"&F$3,tblAsistencias[],6,FALSE)), "", VLOOKUP(TEXT($A7,"aaaa-mm")&"_"&$B$2&"_"&F$3,tblAsistencias[],6,FALSE)), "") | G7: =IFERROR(IF(ISBLANK(VLOOKUP(TEXT($A7,"aaaa-mm")&"_"&$G$2&"_"&G$3,tblAsistencias[],6,FALSE)), "", VLOOKUP(TEXT($A7,"aaaa-mm")&"_"&$G$2&"_"&G$3,tblAsistencias[],6,FALSE)), "") | H7: =IFERROR(IF(ISBLANK(VLOOKUP(TEXT($A7,"aaaa-mm")&"_"&$G$2&"_"&H$3,tblAsistencias[],6,FALSE)), "", VLOOKUP(TEXT($A7,"aaaa-mm")&"_"&$G$2&"_"&H$3,tblAsistencias[],6,FALSE)), "") | I7: =IFERROR(IF(ISBLANK(VLOOKUP(TEXT($A7,"aaaa-mm")&"_"&$G$2&"_"&I$3,tblAsistencias[],6,FALSE)), "", VLOOKUP(TEXT($A7,"aaaa-mm")&"_"&$G$2&"_"&I$3,tblAsistencias[],6,FALSE)), "") | J7: =IFERROR(IF(ISBLANK(VLOOKUP(TEXT($A7,"aaaa-mm")&"_"&$G$2&"_"&J$3,tblAsistencias[],6,FALSE)), "", VLOOKUP(TEXT($A7,"aaaa-mm")&"_"&$G$2&"_"&J$3,tblAsistencias[],6,FALSE)), "") | K7: =IFERROR(IF(ISBLANK(VLOOKUP(TEXT($A7,"aaaa-mm")&"_"&$G$2&"_"&K$3,tblAsistencias[],6,FALSE)), "", VLOOKUP(TEXT($A7,"aaaa-mm")&"_"&$G$2&"_"&K$3,tblAsistencias[],6,FALSE)), "")
A8: 45597 | B8: =IFERROR(IF(ISBLANK(VLOOKUP(TEXT($A8,"aaaa-mm")&"_"&$B$2&"_"&B$3,tblAsistencias[],6,FALSE)), VLOOKUP(TEXT($A8,"aaaa-mm")&"_"&$B$2&"_"&B$3,tblAsistencias[],7,FALSE), VLOOKUP(TEXT($A8,"aaaa-mm")&"_"&$B$2&"_"&B$3,tblAsistencias[],6,FALSE)), "") | C8: =IFERROR(IF(ISBLANK(VLOOKUP(TEXT($A8,"aaaa-mm")&"_"&$B$2&"_"&C$3,tblAsistencias[],6,FALSE)), VLOOKUP(TEXT($A8,"aaaa-mm")&"_"&$B$2&"_"&C$3,tblAsistencias[],7,FALSE), VLOOKUP(TEXT($A8,"aaaa-mm")&"_"&$B$2&"_"&C$3,tblAsistencias[],6,FALSE)), "") | D8: =IFERROR(IF(ISBLANK(VLOOKUP(TEXT($A8,"aaaa-mm")&"_"&$B$2&"_"&D$3,tblAsistencias[],6,FALSE)), VLOOKUP(TEXT($A8,"aaaa-mm")&"_"&$B$2&"_"&D$3,tblAsistencias[],7,FALSE), VLOOKUP(TEXT($A8,"aaaa-mm")&"_"&$B$2&"_"&D$3,tblAsistencias[],6,FALSE)), "") | E8: =IFERROR(IF(ISBLANK(VLOOKUP(TEXT($A8,"aaaa-mm")&"_"&$B$2&"_"&E$3,tblAsistencias[],6,FALSE)), VLOOKUP(TEXT($A8,"aaaa-mm")&"_"&$B$2&"_"&E$3,tblAsistencias[],7,FALSE), VLOOKUP(TEXT($A8,"aaaa-mm")&"_"&$B$2&"_"&E$3,tblAsistencias[],6,FALSE)), "") | F8: =IFERROR(IF(ISBLANK(VLOOKUP(TEXT($A8,"aaaa-mm")&"_"&$B$2&"_"&F$3,tblAsistencias[],6,FALSE)), VLOOKUP(TEXT($A8,"aaaa-mm")&"_"&$B$2&"_"&F$3,tblAsistencias[],7,FALSE), VLOOKUP(TEXT($A8,"aaaa-mm")&"_"&$B$2&"_"&F$3,tblAsistencias[],6,FALSE)), "") | G8: =IFERROR(IF(ISBLANK(VLOOKUP(TEXT($A8,"aaaa-mm")&"_"&$G$2&"_"&G$3,tblAsistencias[],6,FALSE)), VLOOKUP(TEXT($A8,"aaaa-mm")&"_"&$G$2&"_"&G$3,tblAsistencias[],7,FALSE), VLOOKUP(TEXT($A8,"aaaa-mm")&"_"&$G$2&"_"&G$3,tblAsistencias[],6,FALSE)), "") | H8: =IFERROR(IF(ISBLANK(VLOOKUP(TEXT($A8,"aaaa-mm")&"_"&$G$2&"_"&H$3,tblAsistencias[],6,FALSE)), VLOOKUP(TEXT($A8,"aaaa-mm")&"_"&$G$2&"_"&H$3,tblAsistencias[],7,FALSE), VLOOKUP(TEXT($A8,"aaaa-mm")&"_"&$G$2&"_"&H$3,tblAsistencias[],6,FALSE)), "") | I8: =IFERROR(IF(ISBLANK(VLOOKUP(TEXT($A8,"aaaa-mm")&"_"&$G$2&"_"&I$3,tblAsistencias[],6,FALSE)), VLOOKUP(TEXT($A8,"aaaa-mm")&"_"&$G$2&"_"&I$3,tblAsistencias[],7,FALSE), VLOOKUP(TEXT($A8,"aaaa-mm")&"_"&$G$2&"_"&I$3,tblAsistencias[],6,FALSE)), "") | J8: =IFERROR(IF(ISBLANK(VLOOKUP(TEXT($A8,"aaaa-mm")&"_"&$G$2&"_"&J$3,tblAsistencias[],6,FALSE)), VLOOKUP(TEXT($A8,"aaaa-mm")&"_"&$G$2&"_"&J$3,tblAsistencias[],7,FALSE), VLOOKUP(TEXT($A8,"aaaa-mm")&"_"&$G$2&"_"&J$3,tblAsistencias[],6,FALSE)), "") | K8: =IFERROR(IF(ISBLANK(VLOOKUP(TEXT($A8,"aaaa-mm")&"_"&$G$2&"_"&K$3,tblAsistencias[],6,FALSE)), VLOOKUP(TEXT($A8,"aaaa-mm")&"_"&$G$2&"_"&K$3,tblAsistencias[],7,FALSE), VLOOKUP(TEXT($A8,"aaaa-mm")&"_"&$G$2&"_"&K$3,tblAsistencias[],6,FALSE)), "")
A9: 45627 | B9: =IFERROR(IF(ISBLANK(VLOOKUP(TEXT($A9,"aaaa-mm")&"_"&$B$2&"_"&B$3,tblAsistencias[],6,FALSE)), VLOOKUP(TEXT($A9,"aaaa-mm")&"_"&$B$2&"_"&B$3,tblAsistencias[],7,FALSE), VLOOKUP(TEXT($A9,"aaaa-mm")&"_"&$B$2&"_"&B$3,tblAsistencias[],6,FALSE)), "") | C9: =IFERROR(IF(ISBLANK(VLOOKUP(TEXT($A9,"aaaa-mm")&"_"&$B$2&"_"&C$3,tblAsistencias[],6,FALSE)), VLOOKUP(TEXT($A9,"aaaa-mm")&"_"&$B$2&"_"&C$3,tblAsistencias[],7,FALSE), VLOOKUP(TEXT($A9,"aaaa-mm")&"_"&$B$2&"_"&C$3,tblAsistencias[],6,FALSE)), "") | D9: =IFERROR(IF(ISBLANK(VLOOKUP(TEXT($A9,"aaaa-mm")&"_"&$B$2&"_"&D$3,tblAsistencias[],6,FALSE)), VLOOKUP(TEXT($A9,"aaaa-mm")&"_"&$B$2&"_"&D$3,tblAsistencias[],7,FALSE), VLOOKUP(TEXT($A9,"aaaa-mm")&"_"&$B$2&"_"&D$3,tblAsistencias[],6,FALSE)), "") | E9: =IFERROR(IF(ISBLANK(VLOOKUP(TEXT($A9,"aaaa-mm")&"_"&$B$2&"_"&E$3,tblAsistencias[],6,FALSE)), VLOOKUP(TEXT($A9,"aaaa-mm")&"_"&$B$2&"_"&E$3,tblAsistencias[],7,FALSE), VLOOKUP(TEXT($A9,"aaaa-mm")&"_"&$B$2&"_"&E$3,tblAsistencias[],6,FALSE)), "") | F9: =IFERROR(IF(ISBLANK(VLOOKUP(TEXT($A9,"aaaa-mm")&"_"&$B$2&"_"&F$3,tblAsistencias[],6,FALSE)), VLOOKUP(TEXT($A9,"aaaa-mm")&"_"&$B$2&"_"&F$3,tblAsistencias[],7,FALSE), VLOOKUP(TEXT($A9,"aaaa-mm")&"_"&$B$2&"_"&F$3,tblAsistencias[],6,FALSE)), "") | G9: =IFERROR(IF(ISBLANK(VLOOKUP(TEXT($A9,"aaaa-mm")&"_"&$G$2&"_"&G$3,tblAsistencias[],6,FALSE)), VLOOKUP(TEXT($A9,"aaaa-mm")&"_"&$G$2&"_"&G$3,tblAsistencias[],7,FALSE), VLOOKUP(TEXT($A9,"aaaa-mm")&"_"&$G$2&"_"&G$3,tblAsistencias[],6,FALSE)), "") | H9: =IFERROR(IF(ISBLANK(VLOOKUP(TEXT($A9,"aaaa-mm")&"_"&$G$2&"_"&H$3,tblAsistencias[],6,FALSE)), VLOOKUP(TEXT($A9,"aaaa-mm")&"_"&$G$2&"_"&H$3,tblAsistencias[],7,FALSE), VLOOKUP(TEXT($A9,"aaaa-mm")&"_"&$G$2&"_"&H$3,tblAsistencias[],6,FALSE)), "") | I9: =IFERROR(IF(ISBLANK(VLOOKUP(TEXT($A9,"aaaa-mm")&"_"&$G$2&"_"&I$3,tblAsistencias[],6,FALSE)), VLOOKUP(TEXT($A9,"aaaa-mm")&"_"&$G$2&"_"&I$3,tblAsistencias[],7,FALSE), VLOOKUP(TEXT($A9,"aaaa-mm")&"_"&$G$2&"_"&I$3,tblAsistencias[],6,FALSE)), "") | J9: =IFERROR(IF(ISBLANK(VLOOKUP(TEXT($A9,"aaaa-mm")&"_"&$G$2&"_"&J$3,tblAsistencias[],6,FALSE)), VLOOKUP(TEXT($A9,"aaaa-mm")&"_"&$G$2&"_"&J$3,tblAsistencias[],7,FALSE), VLOOKUP(TEXT($A9,"aaaa-mm")&"_"&$G$2&"_"&J$3,tblAsistencias[],6,FALSE)), "") | K9: =IFERROR(IF(ISBLANK(VLOOKUP(TEXT($A9,"aaaa-mm")&"_"&$G$2&"_"&K$3,tblAsistencias[],6,FALSE)), VLOOKUP(TEXT($A9,"aaaa-mm")&"_"&$G$2&"_"&K$3,tblAsistencias[],7,FALSE), VLOOKUP(TEXT($A9,"aaaa-mm")&"_"&$G$2&"_"&K$3,tblAsistencias[],6,FALSE)), "")
A10: 45658 | B10: =IFERROR(IF(ISBLANK(VLOOKUP(TEXT($A10,"aaaa-mm")&"_"&$B$2&"_"&B$3,tblAsistencias[],6,FALSE)), VLOOKUP(TEXT($A10,"aaaa-mm")&"_"&$B$2&"_"&B$3,tblAsistencias[],7,FALSE), VLOOKUP(TEXT($A10,"aaaa-mm")&"_"&$B$2&"_"&B$3,tblAsistencias[],6,FALSE)), "") | C10: =IFERROR(IF(ISBLANK(VLOOKUP(TEXT($A10,"aaaa-mm")&"_"&$B$2&"_"&C$3,tblAsistencias[],6,FALSE)), VLOOKUP(TEXT($A10,"aaaa-mm")&"_"&$B$2&"_"&C$3,tblAsistencias[],7,FALSE), VLOOKUP(TEXT($A10,"aaaa-mm")&"_"&$B$2&"_"&C$3,tblAsistencias[],6,FALSE)), "") | D10: =IFERROR(IF(ISBLANK(VLOOKUP(TEXT($A10,"aaaa-mm")&"_"&$B$2&"_"&D$3,tblAsistencias[],6,FALSE)), VLOOKUP(TEXT($A10,"aaaa-mm")&"_"&$B$2&"_"&D$3,tblAsistencias[],7,FALSE), VLOOKUP(TEXT($A10,"aaaa-mm")&"_"&$B$2&"_"&D$3,tblAsistencias[],6,FALSE)), "") | E10: =IFERROR(IF(ISBLANK(VLOOKUP(TEXT($A10,"aaaa-mm")&"_"&$B$2&"_"&E$3,tblAsistencias[],6,FALSE)), VLOOKUP(TEXT($A10,"aaaa-mm")&"_"&$B$2&"_"&E$3,tblAsistencias[],7,FALSE), VLOOKUP(TEXT($A10,"aaaa-mm")&"_"&$B$2&"_"&E$3,tblAsistencias[],6,FALSE)), "") | F10: =IFERROR(IF(ISBLANK(VLOOKUP(TEXT($A10,"aaaa-mm")&"_"&$B$2&"_"&F$3,tblAsistencias[],6,FALSE)), VLOOKUP(TEXT($A10,"aaaa-mm")&"_"&$B$2&"_"&F$3,tblAsistencias[],7,FALSE), VLOOKUP(TEXT($A10,"aaaa-mm")&"_"&$B$2&"_"&F$3,tblAsistencias[],6,FALSE)), "") | G10: =IFERROR(IF(ISBLANK(VLOOKUP(TEXT($A10,"aaaa-mm")&"_"&$G$2&"_"&G$3,tblAsistencias[],6,FALSE)), VLOOKUP(TEXT($A10,"aaaa-mm")&"_"&$G$2&"_"&G$3,tblAsistencias[],7,FALSE), VLOOKUP(TEXT($A10,"aaaa-mm")&"_"&$G$2&"_"&G$3,tblAsistencias[],6,FALSE)), "") | H10: =IFERROR(IF(ISBLANK(VLOOKUP(TEXT($A10,"aaaa-mm")&"_"&$G$2&"_"&H$3,tblAsistencias[],6,FALSE)), VLOOKUP(TEXT($A10,"aaaa-mm")&"_"&$G$2&"_"&H$3,tblAsistencias[],7,FALSE), VLOOKUP(TEXT($A10,"aaaa-mm")&"_"&$G$2&"_"&H$3,tblAsistencias[],6,FALSE)), "") | I10: =IFERROR(IF(ISBLANK(VLOOKUP(TEXT($A10,"aaaa-mm")&"_"&$G$2&"_"&I$3,tblAsistencias[],6,FALSE)), VLOOKUP(TEXT($A10,"aaaa-mm")&"_"&$G$2&"_"&I$3,tblAsistencias[],7,FALSE), VLOOKUP(TEXT($A10,"aaaa-mm")&"_"&$G$2&"_"&I$3,tblAsistencias[],6,FALSE)), "") | J10: =IFERROR(IF(ISBLANK(VLOOKUP(TEXT($A10,"aaaa-mm")&"_"&$G$2&"_"&J$3,tblAsistencias[],6,FALSE)), VLOOKUP(TEXT($A10,"aaaa-mm")&"_"&$G$2&"_"&J$3,tblAsistencias[],7,FALSE), VLOOKUP(TEXT($A10,"aaaa-mm")&"_"&$G$2&"_"&J$3,tblAsistencias[],6,FALSE)), "") | K10: =IFERROR(IF(ISBLANK(VLOOKUP(TEXT($A10,"aaaa-mm")&"_"&$G$2&"_"&K$3,tblAsistencias[],6,FALSE)), VLOOKUP(TEXT($A10,"aaaa-mm")&"_"&$G$2&"_"&K$3,tblAsistencias[],7,FALSE), VLOOKUP(TEXT($A10,"aaaa-mm")&"_"&$G$2&"_"&K$3,tblAsistencias[],6,FALSE)), "")
A11: 45689 | B11: =IFERROR(IF(ISBLANK(VLOOKUP(TEXT($A11,"aaaa-mm")&"_"&$B$2&"_"&B$3,tblAsistencias[],6,FALSE)), VLOOKUP(TEXT($A11,"aaaa-mm")&"_"&$B$2&"_"&B$3,tblAsistencias[],7,FALSE), VLOOKUP(TEXT($A11,"aaaa-mm")&"_"&$B$2&"_"&B$3,tblAsistencias[],6,FALSE)), "") | C11: =IFERROR(IF(ISBLANK(VLOOKUP(TEXT($A11,"aaaa-mm")&"_"&$B$2&"_"&C$3,tblAsistencias[],6,FALSE)), VLOOKUP(TEXT($A11,"aaaa-mm")&"_"&$B$2&"_"&C$3,tblAsistencias[],7,FALSE), VLOOKUP(TEXT($A11,"aaaa-mm")&"_"&$B$2&"_"&C$3,tblAsistencias[],6,FALSE)), "") | D11: =IFERROR(IF(ISBLANK(VLOOKUP(TEXT($A11,"aaaa-mm")&"_"&$B$2&"_"&D$3,tblAsistencias[],6,FALSE)), VLOOKUP(TEXT($A11,"aaaa-mm")&"_"&$B$2&"_"&D$3,tblAsistencias[],7,FALSE), VLOOKUP(TEXT($A11,"aaaa-mm")&"_"&$B$2&"_"&D$3,tblAsistencias[],6,FALSE)), "") | E11: =IFERROR(IF(ISBLANK(VLOOKUP(TEXT($A11,"aaaa-mm")&"_"&$B$2&"_"&E$3,tblAsistencias[],6,FALSE)), VLOOKUP(TEXT($A11,"aaaa-mm")&"_"&$B$2&"_"&E$3,tblAsistencias[],7,FALSE), VLOOKUP(TEXT($A11,"aaaa-mm")&"_"&$B$2&"_"&E$3,tblAsistencias[],6,FALSE)), "") | F11: =IFERROR(IF(ISBLANK(VLOOKUP(TEXT($A11,"aaaa-mm")&"_"&$B$2&"_"&F$3,tblAsistencias[],6,FALSE)), VLOOKUP(TEXT($A11,"aaaa-mm")&"_"&$B$2&"_"&F$3,tblAsistencias[],7,FALSE), VLOOKUP(TEXT($A11,"aaaa-mm")&"_"&$B$2&"_"&F$3,tblAsistencias[],6,FALSE)), "") | G11: =IFERROR(IF(ISBLANK(VLOOKUP(TEXT($A11,"aaaa-mm")&"_"&$G$2&"_"&G$3,tblAsistencias[],6,FALSE)), VLOOKUP(TEXT($A11,"aaaa-mm")&"_"&$G$2&"_"&G$3,tblAsistencias[],7,FALSE), VLOOKUP(TEXT($A11,"aaaa-mm")&"_"&$G$2&"_"&G$3,tblAsistencias[],6,FALSE)), "") | H11: =IFERROR(IF(ISBLANK(VLOOKUP(TEXT($A11,"aaaa-mm")&"_"&$G$2&"_"&H$3,tblAsistencias[],6,FALSE)), VLOOKUP(TEXT($A11,"aaaa-mm")&"_"&$G$2&"_"&H$3,tblAsistencias[],7,FALSE), VLOOKUP(TEXT($A11,"aaaa-mm")&"_"&$G$2&"_"&H$3,tblAsistencias[],6,FALSE)), "") | I11: =IFERROR(IF(ISBLANK(VLOOKUP(TEXT($A11,"aaaa-mm")&"_"&$G$2&"_"&I$3,tblAsistencias[],6,FALSE)), VLOOKUP(TEXT($A11,"aaaa-mm")&"_"&$G$2&"_"&I$3,tblAsistencias[],7,FALSE), VLOOKUP(TEXT($A11,"aaaa-mm")&"_"&$G$2&"_"&I$3,tblAsistencias[],6,FALSE)), "") | J11: =IFERROR(IF(ISBLANK(VLOOKUP(TEXT($A11,"aaaa-mm")&"_"&$G$2&"_"&J$3,tblAsistencias[],6,FALSE)), VLOOKUP(TEXT($A11,"aaaa-mm")&"_"&$G$2&"_"&J$3,tblAsistencias[],7,FALSE), VLOOKUP(TEXT($A11,"aaaa-mm")&"_"&$G$2&"_"&J$3,tblAsistencias[],6,FALSE)), "") | K11: =IFERROR(IF(ISBLANK(VLOOKUP(TEXT($A11,"aaaa-mm")&"_"&$G$2&"_"&K$3,tblAsistencias[],6,FALSE)), VLOOKUP(TEXT($A11,"aaaa-mm")&"_"&$G$2&"_"&K$3,tblAsistencias[],7,FALSE), VLOOKUP(TEXT($A11,"aaaa-mm")&"_"&$G$2&"_"&K$3,tblAsistencias[],6,FALSE)), "")
